Workbook

Sheet 대치메가 9월 신고
A1: 6 | B1: 이름 | C1: 주민번호 | D1: 입사일 | E1: 근무요일 | F1: 근무시간 | G1: 현재 주 소정근로시간 법정 휴게제외 | H1: 일 휴게시간 | I1: 조정 후 주 소정근로시간 | J1: 실급여 | K1: 신고 급여 | L1: 특이사항 | M1: 만근수당대상 | N1: 지급여부 | O1: 비고 | P1: 6월 최초 | Q1: 6월 수정
A2: 1 | B2: 배은솔 | D2: 2023.05.25 | E2: 평일 | F2: 점주 | J2: =sumif('대치 9월 주급여'!$M$2:$Q$16, B2, '대치 9월 주급여'!$S$2:$S$16)+sumif('삼성 9월 주급여'!$M$2:$Q$20, B2, '삼성 9월 주급여'!$Q$2:$Q$20) -> 2255747 | K2: =J2 -> 2255747 | L2: 점주
A3: 2 | B3: 김석원 | C3: 980210-1083216 | D3: 2025.05.21 | E3: 평일 | F3: 22:30~06:30 | J3: =sumif('대치 9월 주급여'!$M$2:$Q$16, B3, '대치 9월 주급여'!$S$2:$S$16)+sumif('삼성 9월 주급여'!$M$2:$Q$20, B3, '삼성 9월 주급여'!$S$2:$S$20) -> 2314530 | K3: =sumif('대치 9월 주급여'!$M$2:$Q$16, B3, '대치 9월 주급여'!$Q$2:$Q$16)+sumif('삼성 9월 주급여'!$M$2:$Q$20, B3, '삼성 9월 주급여'!$Q$2:$Q$20) -> 2393510 | L3: 3.3% 사업소득신고
A4: 3 | B4: 김현지 | C4: 060519-4686218 | D4: 2024.02.27 | E4: 화, 목 토, 일 | F4: 15:00~18:30 16:00~23:00 | G4: 21 | J4: =sumif('대치 9월 주급여'!$M$2:$Q$16, B4, '대치 9월 주급여'!$S$2:$S$16)+sumif('삼성 9월 주급여'!$M$2:$Q$20, B4, '삼성 9월 주급여'!$S$2:$S$20) -> 1006764 | K4: =sumif('대치 9월 주급여'!$M$2:$Q$16, B4, '대치 9월 주급여'!$Q$2:$Q$16)+sumif('삼성 9월 주급여'!$M$2:$Q$20, B4, '삼성 9월 주급여'!$Q$2:$Q$20) -> 1041114 | L4: 3.3% 사업소득신고
A5: 4 | B5: 문병준 | C5: 970828-1019729 | D5: 2024.08.07 | E5: 월, 수, 금 | F5: 18:30~23:00 | G5: 13.5 | J5: =sumif('대치 9월 주급여'!$M$2:$Q$16, B5, '대치 9월 주급여'!$S$2:$S$16)+sumif('삼성 9월 주급여'!$M$2:$Q$20, B5, '삼성 9월 주급여'!$S$2:$S$20) -> 694890 | K5: =sumif('대치 9월 주급여'!$M$2:$Q$16, B5, '대치 9월 주급여'!$Q$2:$Q$16)+sumif('삼성 9월 주급여'!$M$2:$Q$20, B5, '삼성 9월 주급여'!$Q$2:$Q$20) -> 694890 | L5: 주15시간 미만
A6: 5 | B6: 안지혜 | C6: 021220-4069418 | D6: 2025.05.10 | E6: 토, 일 | F6: 12:00~16:00 | G6: 8 | J6: =sumif('대치 9월 주급여'!$M$2:$Q$16, B6, '대치 9월 주급여'!$S$2:$S$16)+sumif('삼성 9월 주급여'!$M$2:$Q$20, B6, '삼성 9월 주급여'!$S$2:$S$20) -> 424655 | K6: =sumif('대치 9월 주급여'!$M$2:$Q$16, B6, '대치 9월 주급여'!$Q$2:$Q$16)+sumif('삼성 9월 주급여'!$M$2:$Q$20, B6, '삼성 9월 주급여'!$Q$2:$Q$20) -> 424655 | L6: 주15시간 미만
A7: 6 | B7: 알리사 | C7: 020527-8780077 | D7: 2024.03.09 | E7: 화, 목 토, 일 | F7: 18:30~23:00 07:00~12:00 | G7: 19 | J7: =sumif('대치 9월 주급여'!$M$2:$Q$16, B7, '대치 9월 주급여'!$S$2:$S$16)+sumif('삼성 9월 주급여'!$M$2:$Q$20, B7, '삼성 9월 주급여'!$S$2:$S$20) -> 842857 | K7: =sumif('대치 9월 주급여'!$M$2:$Q$16, B7, '대치 9월 주급여'!$Q$2:$Q$16)+sumif('삼성 9월 주급여'!$M$2:$Q$20, B7, '삼성 9월 주급여'!$Q$2:$Q$20) -> 871607 | L7: 주15시간 미만
A8: 7 | B8: 이주형 | C8: 901128-1851613 | D8: 2025.05.17 | E8: 금,토 | F8: 23:00~07:00 | G8: 17 | J8: =sumif('대치 9월 주급여'!$M$2:$Q$16, B8, '대치 9월 주급여'!$S$2:$S$16)+sumif('삼성 9월 주급여'!$M$2:$Q$20, B8, '삼성 9월 주급여'!$S$2:$S$20) -> 902358 | K8: =sumif('대치 9월 주급여'!$M$2:$Q$16, B8, '대치 9월 주급여'!$Q$2:$Q$16)+sumif('삼성 9월 주급여'!$M$2:$Q$20, B8, '삼성 9월 주급여'!$Q$2:$Q$20) -> 933138 | L8: 3.3% 사업소득신고
A9: 8 | B9: 권민석 | C9: 040222-3057215 | D9: 2025.07.16 | E9: 일용직 | F9: - | G9: - | J9: =sumif('대치 9월 주급여'!$M$2:$Q$16, B9, '대치 9월 주급여'!$S$2:$S$16)+sumif('삼성 9월 주급여'!$M$2:$Q$20, B9, '삼성 9월 주급여'!$S$2:$S$20) -> 371110 | K9: =sumif('대치 9월 주급여'!$M$2:$Q$16, B9, '대치 9월 주급여'!$Q$2:$Q$16)+sumif('삼성 9월 주급여'!$M$2:$Q$20, B9, '삼성 9월 주급여'!$Q$2:$Q$20) -> 371110 | L9: 주15시간 미만 | O9: 9월 퇴사
A10: 9 | B10: 배익순 | C10: 630215-1066929 | D10: 2025.04.01 | E10: - | F10: - | J10: 0 | K10: 400000 | L10: 3.3% 사업소득신고 | O10: 직계가족
A11: 10 | B11: 유성심 | C11: 720808-2029819 | D11: 2024.01.01 | E11: - | F11: - | G11: 14 | J11: 0 | K11: 580000 | L11: 주15시간 미만 | O11: 가용인원
A12: 11 | B12: 최지혜 | C12: 810208-2041516 | D12: 2024.01.01 | E12: - | F12: - | G12: 14 | J12: 0 | K12: 580000 | L12: 주15시간 미만 | O12: 가용인원
J13: =sum(J4:J10) -> 4242634 | K13: =sum(K4:K10) -> 4736514

Sheet 대치메가 9월 급여
A1: ㅇ | C1: 월요일 | H1: 화요일 | M1: 수요일 | R1: 목요일 | W1: 금요일 | AB1: 토요일 | AG1: 일요일
A2: 구분 | C2: 이름 | D2: 시작시간 | E2: 종료시간 | F2: 비고 | G2: 근무시간 | H2: 이름 | I2: 시작시간 | J2: 종료시간 | L2: 근무시간 | M2: 이름 | N2: 시작시간 | O2: 종료시간 | P2: 비고 | Q2: 근무시간 | R2: 이름 | S2: 시작시간 | T2: 종료시간 | U2: 비고 | V2: 근무시간 | W2: 이름 | X2: 시작시간 | Y2: 종료시간 | Z2: 비고 | AA2: 근무시간 | AB2: 이름 | AC2: 시작시간 | AD2: 종료시간 | AE2: 비고 | AF2: 근무시간 | AG2: 이름 | AH2: 시작시간 | AI2: 종료시간 | AJ2: 비고 | AK2: 근무시간
B3: 일자 | C3: 1 | G3: =if(E3-D3 < 0 , (E3-D3+1)*24, (E3-D3)*24) -> 0 | H3: 2 | L3: =if(J3-I3 < 0 , (J3-I3+1)*24, (J3-I3)*24) -> 0 | M3: 3 | Q3: =if(O3-N3 < 0 , (O3-N3+1)*24, (O3-N3)*24) -> 0 | R3: 4 | V3: =if(T3-S3 < 0 , (T3-S3+1)*24, (T3-S3)*24) -> 0 | W3: 5 | AA3: =if(Y3-X3 < 0 , (Y3-X3+1)*24, (Y3-X3)*24) -> 0 | AB3: 2 | AF3: =if(AD3-AC3 < 0 , (AD3-AC3+1)*24, (AD3-AC3)*24) -> 0 | AG3: 7 | AK3: =if(AI3-AH3 < 0 , (AI3-AH3+1)*24, (AI3-AH3)*24) -> 0
A4: 1주차 | B4: 1 | C4: 강순옥 | D4: 0.27083333 | E4: 0.625 | G4: =if(E4-D4 < 0 , (E4-D4+1)*24, (E4-D4)*24) -> 8.5 | H4: 강순옥 | I4: 0.27083333 | J4: 0.625 | L4: =if(J4-I4 < 0 , (J4-I4+1)*24, (J4-I4)*24) -> 8.5 | M4: 강순옥 | N4: 0.27083333 | O4: 0.625 | Q4: =if(O4-N4 < 0 , (O4-N4+1)*24, (O4-N4)*24) -> 8.5 | R4: 강순옥 | S4: 0.27083333 | T4: 0.625 | V4: =if(T4-S4 < 0 , (T4-S4+1)*24, (T4-S4)*24) -> 8.5 | W4: 강순옥 | X4: 0.27083333 | Y4: 0.625 | AA4: =if(Y4-X4 < 0 , (Y4-X4+1)*24, (Y4-X4)*24) -> 8.5 | AB4: 알리사 | AC4: 0.30208333 | AD4: 0.51041667 | AF4: =if(AD4-AC4 < 0 , (AD4-AC4+1)*24, (AD4-AC4)*24) -> 5 | AG4: 알리사 | AH4: 0.30208333 | AI4: 0.51041667 | AK4: =if(AI4-AH4 < 0 , (AI4-AH4+1)*24, (AI4-AH4)*24) -> 5
A5: 1주차 | B5: 2 | C5: 문병준 | D5: 0.625 | E5: 0.95833333 | G5: =if(E5-D5 < 0 , (E5-D5+1)*24, (E5-D5)*24) -> 8 | H5: 김현지 | I5: 0.625 | J5: 0.77083333 | L5: =if(J5-I5 < 0 , (J5-I5+1)*24, (J5-I5)*24) -> 3.5 | M5: 배은솔 | N5: 0.625 | O5: 0.77083333 | Q5: =if(O5-N5 < 0 , (O5-N5+1)*24, (O5-N5)*24) -> 3.5 | R5: 김현지 | S5: 0.625 | T5: 0.77083333 | V5: =if(T5-S5 < 0 , (T5-S5+1)*24, (T5-S5)*24) -> 3.5 | W5: 배은솔 | X5: 0.625 | Y5: 0.77083333 | AA5: =if(Y5-X5 < 0 , (Y5-X5+1)*24, (Y5-X5)*24) -> 3.5 | AB5: 안지혜 | AC5: 0.5 | AD5: 0.6875 | AF5: =if(AD5-AC5 < 0 , (AD5-AC5+1)*24, (AD5-AC5)*24) -> 4.5 | AG5: 안지혜 | AH5: 0.5 | AI5: 0.6875 | AK5: =if(AI5-AH5 < 0 , (AI5-AH5+1)*24, (AI5-AH5)*24) -> 4.5
A6: 1주차 | B6: 3 | C6: 김석원 | D6: 0.91666667 | E6: 0.27083333 | G6: =if(E6-D6 < 0 , (E6-D6+1)*24, (E6-D6)*24) -> 8.5 | H6: 알리사 | I6: 0.77083333 | J6: 0.95833333 | L6: =if(J6-I6 < 0 , (J6-I6+1)*24, (J6-I6)*24) -> 4.5 | M6: 최제일 | N6: 0.77083333 | O6: 0.95833333 | Q6: =if(O6-N6 < 0 , (O6-N6+1)*24, (O6-N6)*24) -> 4.5 | R6: 알리사 | S6: 0.77083333 | T6: 0.95833333 | V6: =if(T6-S6 < 0 , (T6-S6+1)*24, (T6-S6)*24) -> 4.5 | W6: 문병준 | X6: 0.77083333 | Y6: 0.95833333 | AA6: =if(Y6-X6 < 0 , (Y6-X6+1)*24, (Y6-X6)*24) -> 4.5 | AB6: 김현지 | AC6: 0.66666667 | AD6: 0.95833333 | AF6: =if(AD6-AC6 < 0 , (AD6-AC6+1)*24, (AD6-AC6)*24) -> 7 | AG6: 김현지 | AH6: 0.6875 | AI6: 0.95833333 | AK6: =if(AI6-AH6 < 0 , (AI6-AH6+1)*24, (AI6-AH6)*24) -> 6.5
A7: 1주차 | B7: 4 | G7: =if(E7-D7 < 0 , (E7-D7+1)*24, (E7-D7)*24) -> 0 | H7: 김석원 | I7: 0.91666667 | J7: 0.27083333 | L7: =if(J7-I7 < 0 , (J7-I7+1)*24, (J7-I7)*24) -> 8.5 | M7: 김석원 | N7: 0.91666667 | O7: 0.27083333 | Q7: =if(O7-N7 < 0 , (O7-N7+1)*24, (O7-N7)*24) -> 8.5 | R7: 김석원 | S7: 0.91666667 | T7: 0.27083333 | V7: =if(T7-S7 < 0 , (T7-S7+1)*24, (T7-S7)*24) -> 8.5 | W7: 이주형 | X7: 0.91666667 | Y7: 0.30208333 | AA7: =if(Y7-X7 < 0 , (Y7-X7+1)*24, (Y7-X7)*24) -> 9.25 | AB7: 이주형 | AC7: 0.94791667 | AD7: 0.30208333 | AF7: =if(AD7-AC7 < 0 , (AD7-AC7+1)*24, (AD7-AC7)*24) -> 8.5 | AG7: 김석원 | AH7: 0.95833333 | AI7: 0.29166667 | AK7: =if(AI7-AH7 < 0 , (AI7-AH7+1)*24, (AI7-AH7)*24) -> 8
A8: 1주차 | B8: 5 | G8: =if(E8-D8 < 0 , (E8-D8+1)*24, (E8-D8)*24) -> 0 | L8: =if(J8-I8 < 0 , (J8-I8+1)*24, (J8-I8)*24) -> 0 | Q8: =if(O8-N8 < 0 , (O8-N8+1)*24, (O8-N8)*24) -> 0 | V8: =if(T8-S8 < 0 , (T8-S8+1)*24, (T8-S8)*24) -> 0 | AA8: =if(Y8-X8 < 0 , (Y8-X8+1)*24, (Y8-X8)*24) -> 0 | AF8: =if(AD8-AC8 < 0 , (AD8-AC8+1)*24, (AD8-AC8)*24) -> 0 | AK8: =if(AI8-AH8 < 0 , (AI8-AH8+1)*24, (AI8-AH8)*24) -> 0
B9: 일자 | C9: 8 | G9: =if(E9-D9 < 0 , (E9-D9+1)*24, (E9-D9)*24) -> 0 | H9: 9 | L9: =if(J9-I9 < 0 , (J9-I9+1)*24, (J9-I9)*24) -> 0 | M9: 10 | Q9: =if(O9-N9 < 0 , (O9-N9+1)*24, (O9-N9)*24) -> 0 | R9: 11 | V9: =if(T9-S9 < 0 , (T9-S9+1)*24, (T9-S9)*24) -> 0 | W9: 12 | AA9: =if(Y9-X9 < 0 , (Y9-X9+1)*24, (Y9-X9)*24) -> 0 | AB9: 13 | AF9: =if(AD9-AC9 < 0 , (AD9-AC9+1)*24, (AD9-AC9)*24) -> 0 | AG9: 14 | AK9: =if(AI9-AH9 < 0 , (AI9-AH9+1)*24, (AI9-AH9)*24) -> 0
A10: 2주차 | B10: 1 | C10: 강순옥 | D10: 0.27083333 | E10: 0.625 | G10: =if(E10-D10 < 0 , (E10-D10+1)*24, (E10-D10)*24) -> 8.5 | H10: 강순옥 | I10: 0.27083333 | J10: 0.625 | L10: =if(J10-I10 < 0 , (J10-I10+1)*24, (J10-I10)*24) -> 8.5 | M10: 강순옥 | N10: 0.27083333 | O10: 0.66666667 | Q10: =if(O10-N10 < 0 , (O10-N10+1)*24, (O10-N10)*24) -> 9.5 | R10: 강순옥 | S10: 0.27083333 | T10: 0.625 | V10: =if(T10-S10 < 0 , (T10-S10+1)*24, (T10-S10)*24) -> 8.5 | W10: 강순옥 | X10: 0.27083333 | Y10: 0.625 | AA10: =if(Y10-X10 < 0 , (Y10-X10+1)*24, (Y10-X10)*24) -> 8.5 | AB10: 알리사 | AC10: 0.30208333 | AD10: 0.51041667 | AF10: =if(AD10-AC10 < 0 , (AD10-AC10+1)*24, (AD10-AC10)*24) -> 5 | AG10: 알리사 | AH10: 0.30208333 | AI10: 0.51041667 | AK10: =if(AI10-AH10 < 0 , (AI10-AH10+1)*24, (AI10-AH10)*24) -> 5
A11: 2주차 | B11: 2 | C11: 배은솔 | D11: 0.625 | E11: 0.77083333 | G11: =if(E11-D11 < 0 , (E11-D11+1)*24, (E11-D11)*24) -> 3.5 | H11: 김현지 | I11: 0.625 | J11: 0.77083333 | L11: =if(J11-I11 < 0 , (J11-I11+1)*24, (J11-I11)*24) -> 3.5 | M11: 문병준 | N11: 0.66666667 | O11: 0.95833333 | Q11: =if(O11-N11 < 0 , (O11-N11+1)*24, (O11-N11)*24) -> 7 | R11: 김현지 | S11: 0.625 | T11: 0.77083333 | V11: =if(T11-S11 < 0 , (T11-S11+1)*24, (T11-S11)*24) -> 3.5 | W11: 배은솔 | X11: 0.625 | Y11: 0.77083333 | AA11: =if(Y11-X11 < 0 , (Y11-X11+1)*24, (Y11-X11)*24) -> 3.5 | AB11: 안지혜 | AC11: 0.5 | AD11: 0.6875 | AF11: =if(AD11-AC11 < 0 , (AD11-AC11+1)*24, (AD11-AC11)*24) -> 4.5 | AG11: 안지혜 | AH11: 0.5 | AI11: 0.66666667 | AK11: =if(AI11-AH11 < 0 , (AI11-AH11+1)*24, (AI11-AH11)*24) -> 4
A12: 2주차 | B12: 3 | C12: 문병준 | D12: 0.77083333 | E12: 0.95833333 | G12: =if(E12-D12 < 0 , (E12-D12+1)*24, (E12-D12)*24) -> 4.5 | H12: 알리사 | I12: 0.77083333 | J12: 0.95833333 | L12: =if(J12-I12 < 0 , (J12-I12+1)*24, (J12-I12)*24) -> 4.5 | M12: 김석원 | N12: 0.91666667 | O12: 0.27083333 | Q12: =if(O12-N12 < 0 , (O12-N12+1)*24, (O12-N12)*24) -> 8.5 | R12: 알리사 | S12: 0.77083333 | T12: 0.95833333 | V12: =if(T12-S12 < 0 , (T12-S12+1)*24, (T12-S12)*24) -> 4.5 | W12: 문병준 | X12: 0.77083333 | Y12: 0.95833333 | AA12: =if(Y12-X12 < 0 , (Y12-X12+1)*24, (Y12-X12)*24) -> 4.5 | AB12: 김현지 | AC12: 0.66666667 | AD12: 0.95833333 | AF12: =if(AD12-AC12 < 0 , (AD12-AC12+1)*24, (AD12-AC12)*24) -> 7 | AG12: 김현지 | AH12: 0.66666667 | AI12: 0.95833333 | AK12: =if(AI12-AH12 < 0 , (AI12-AH12+1)*24, (AI12-AH12)*24) -> 7
A13: 2주차 | B13: 4 | C13: 김석원 | D13: 0.91666667 | E13: 0.27083333 | G13: =if(E13-D13 < 0 , (E13-D13+1)*24, (E13-D13)*24) -> 8.5 | H13: 김석원 | I13: 0.91666667 | J13: 0.27083333 | L13: =if(J13-I13 < 0 , (J13-I13+1)*24, (J13-I13)*24) -> 8.5 | Q13: =if(O13-N13 < 0 , (O13-N13+1)*24, (O13-N13)*24) -> 0 | R13: 김석원 | S13: 0.91666667 | T13: 0.27083333 | V13: =if(T13-S13 < 0 , (T13-S13+1)*24, (T13-S13)*24) -> 8.5 | W13: 이주형 | X13: 0.91666667 | Y13: 0.30208333 | AA13: =if(Y13-X13 < 0 , (Y13-X13+1)*24, (Y13-X13)*24) -> 9.25 | AB13: 이주형 | AC13: 0.94791667 | AD13: 0.30208333 | AF13: =if(AD13-AC13 < 0 , (AD13-AC13+1)*24, (AD13-AC13)*24) -> 8.5 | AG13: 김석원 | AH13: 0.95833333 | AI13: 0.29166667 | AK13: =if(AI13-AH13 < 0 , (AI13-AH13+1)*24, (AI13-AH13)*24) -> 8
A14: 2주차 | B14: 5 | G14: =if(E14-D14 < 0 , (E14-D14+1)*24, (E14-D14)*24) -> 0 | L14: =if(J14-I14 < 0 , (J14-I14+1)*24, (J14-I14)*24) -> 0 | Q14: =if(O14-N14 < 0 , (O14-N14+1)*24, (O14-N14)*24) -> 0 | V14: =if(T14-S14 < 0 , (T14-S14+1)*24, (T14-S14)*24) -> 0 | AA14: =if(Y14-X14 < 0 , (Y14-X14+1)*24, (Y14-X14)*24) -> 0 | AF14: =if(AD14-AC14 < 0 , (AD14-AC14+1)*24, (AD14-AC14)*24) -> 0 | AK14: =if(AI14-AH14 < 0 , (AI14-AH14+1)*24, (AI14-AH14)*24) -> 0
B15: 일자 | C15: 15 | G15: =if(E15-D15 < 0 , (E15-D15+1)*24, (E15-D15)*24) -> 0 | H15: 16 | L15: =if(J15-I15 < 0 , (J15-I15+1)*24, (J15-I15)*24) -> 0 | M15: 17 | Q15: =if(O15-N15 < 0 , (O15-N15+1)*24, (O15-N15)*24) -> 0 | R15: 18 | V15: =if(T15-S15 < 0 , (T15-S15+1)*24, (T15-S15)*24) -> 0 | W15: 19 | AA15: =if(Y15-X15 < 0 , (Y15-X15+1)*24, (Y15-X15)*24) -> 0 | AB15: 20 | AF15: =if(AD15-AC15 < 0 , (AD15-AC15+1)*24, (AD15-AC15)*24) -> 0 | AG15: 21 | AK15: =if(AI15-AH15 < 0 , (AI15-AH15+1)*24, (AI15-AH15)*24) -> 0
A16: 3주차 | B16: 1 | C16: 강순옥 | D16: 0.27083333 | E16: 0.625 | G16: =if(E16-D16 < 0 , (E16-D16+1)*24, (E16-D16)*24) -> 8.5 | H16: 강순옥 | I16: 0.27083333 | J16: 0.625 | L16: =if(J16-I16 < 0 , (J16-I16+1)*24, (J16-I16)*24) -> 8.5 | M16: 강순옥 | N16: 0.27083333 | O16: 0.625 | Q16: =if(O16-N16 < 0 , (O16-N16+1)*24, (O16-N16)*24) -> 8.5 | R16: 강순옥 | S16: 0.27083333 | T16: 0.625 | V16: =if(T16-S16 < 0 , (T16-S16+1)*24, (T16-S16)*24) -> 8.5 | W16: 강순옥 | X16: 0.27083333 | Y16: 0.625 | AA16: =if(Y16-X16 < 0 , (Y16-X16+1)*24, (Y16-X16)*24) -> 8.5 | AB16: 알리사 | AC16: 0.30208333 | AD16: 0.51041667 | AF16: =if(AD16-AC16 < 0 , (AD16-AC16+1)*24, (AD16-AC16)*24) -> 5 | AG16: 알리사 | AH16: 0.30208333 | AI16: 0.51041667 | AK16: =if(AI16-AH16 < 0 , (AI16-AH16+1)*24, (AI16-AH16)*24) -> 5
A17: 3주차 | B17: 2 | C17: 배은솔 | D17: 0.625 | E17: 0.77083333 | G17: =if(E17-D17 < 0 , (E17-D17+1)*24, (E17-D17)*24) -> 3.5 | H17: 김현지 | I17: 0.625 | J17: 0.77083333 | L17: =if(J17-I17 < 0 , (J17-I17+1)*24, (J17-I17)*24) -> 3.5 | M17: 문병준 | N17: 0.64583333 | O17: 0.95833333 | Q17: =if(O17-N17 < 0 , (O17-N17+1)*24, (O17-N17)*24) -> 7.5 | R17: 김현지 | S17: 0.625 | T17: 0.77083333 | V17: =if(T17-S17 < 0 , (T17-S17+1)*24, (T17-S17)*24) -> 3.5 | W17: 배은솔 | X17: 0.625 | Y17: 0.77083333 | AA17: =if(Y17-X17 < 0 , (Y17-X17+1)*24, (Y17-X17)*24) -> 3.5 | AB17: 안지혜 | AC17: 0.5 | AD17: 0.6875 | AF17: =if(AD17-AC17 < 0 , (AD17-AC17+1)*24, (AD17-AC17)*24) -> 4.5 | AG17: 안지혜 | AH17: 0.5 | AI17: 0.66666667 | AK17: =if(AI17-AH17 < 0 , (AI17-AH17+1)*24, (AI17-AH17)*24) -> 4
A18: 3주차 | B18: 3 | C18: 문병준 | D18: 0.77083333 | E18: 0.95833333 | G18: =if(E18-D18 < 0 , (E18-D18+1)*24, (E18-D18)*24) -> 4.5 | H18: 알리사 | I18: 0.77083333 | J18: 0.95833333 | L18: =if(J18-I18 < 0 , (J18-I18+1)*24, (J18-I18)*24) -> 4.5 | M18: 김석원 | N18: 0.91666667 | O18: 0.27083333 | Q18: =if(O18-N18 < 0 , (O18-N18+1)*24, (O18-N18)*24) -> 8.5 | R18: 알리사 | S18: 0.77083333 | T18: 0.95833333 | V18: =if(T18-S18 < 0 , (T18-S18+1)*24, (T18-S18)*24) -> 4.5 | W18: 문병준 | X18: 0.77083333 | Y18: 0.95833333 | AA18: =if(Y18-X18 < 0 , (Y18-X18+1)*24, (Y18-X18)*24) -> 4.5 | AB18: 김현지 | AC18: 0.66666667 | AD18: 0.95833333 | AF18: =if(AD18-AC18 < 0 , (AD18-AC18+1)*24, (AD18-AC18)*24) -> 7 | AG18: 김현지 | AH18: 0.66666667 | AI18: 0.95833333 | AK18: =if(AI18-AH18 < 0 , (AI18-AH18+1)*24, (AI18-AH18)*24) -> 7
A19: 3주차 | B19: 4 | C19: 김석원 | D19: 0.91666667 | E19: 0.27083333 | G19: =if(E19-D19 < 0 , (E19-D19+1)*24, (E19-D19)*24) -> 8.5 | H19: 김석원 | I19: 0.91666667 | J19: 0.27083333 | L19: =if(J19-I19 < 0 , (J19-I19+1)*24, (J19-I19)*24) -> 8.5 | Q19: =if(O19-N19 < 0 , (O19-N19+1)*24, (O19-N19)*24) -> 0 | R19: 김석원 | S19: 0.91666667 | T19: 0.27083333 | V19: =if(T19-S19 < 0 , (T19-S19+1)*24, (T19-S19)*24) -> 8.5 | W19: 이주형 | X19: 0.91666667 | Y19: 0.30208333 | AA19: =if(Y19-X19 < 0 , (Y19-X19+1)*24, (Y19-X19)*24) -> 9.25 | AB19: 이주형 | AC19: 0.94791667 | AD19: 0.30208333 | AF19: =if(AD19-AC19 < 0 , (AD19-AC19+1)*24, (AD19-AC19)*24) -> 8.5 | AG19: 김석원 | AH19: 0.95833333 | AI19: 0.29166667 | AK19: =if(AI19-AH19 < 0 , (AI19-AH19+1)*24, (AI19-AH19)*24) -> 8
A20: 3주차 | B20: 5 | G20: =if(E20-D20 < 0 , (E20-D20+1)*24, (E20-D20)*24) -> 0 | L20: =if(J20-I20 < 0 , (J20-I20+1)*24, (J20-I20)*24) -> 0 | Q20: =if(O20-N20 < 0 , (O20-N20+1)*24, (O20-N20)*24) -> 0 | V20: =if(T20-S20 < 0 , (T20-S20+1)*24, (T20-S20)*24) -> 0 | AA20: =if(Y20-X20 < 0 , (Y20-X20+1)*24, (Y20-X20)*24) -> 0 | AF20: =if(AD20-AC20 < 0 , (AD20-AC20+1)*24, (AD20-AC20)*24) -> 0 | AK20: =if(AI20-AH20 < 0 , (AI20-AH20+1)*24, (AI20-AH20)*24) -> 0
B21: 일자 | C21: 22 | G21: =if(E21-D21 < 0 , (E21-D21+1)*24, (E21-D21)*24) -> 0 | H21: 23 | L21: =if(J21-I21 < 0 , (J21-I21+1)*24, (J21-I21)*24) -> 0 | M21: 24 | Q21: =if(O21-N21 < 0 , (O21-N21+1)*24, (O21-N21)*24) -> 0 | R21: 25 | V21: =if(T21-S21 < 0 , (T21-S21+1)*24, (T21-S21)*24) -> 0 | W21: 26 | AA21: =if(Y21-X21 < 0 , (Y21-X21+1)*24, (Y21-X21)*24) -> 0 | AB21: 27 | AF21: =if(AD21-AC21 < 0 , (AD21-AC21+1)*24, (AD21-AC21)*24) -> 0 | AG21: 28 | AK21: =if(AI21-AH21 < 0 , (AI21-AH21+1)*24, (AI21-AH21)*24) -> 0
A22: 4주차 | B22: 1 | C22: 강순옥 | D22: 0.27083333 | E22: 0.625 | G22: =if(E22-D22 < 0 , (E22-D22+1)*24, (E22-D22)*24) -> 8.5 | H22: 강순옥 | I22: 0.27083333 | J22: 0.625 | L22: =if(J22-I22 < 0 , (J22-I22+1)*24, (J22-I22)*24) -> 8.5 | M22: 강순옥 | N22: 0.27083333 | O22: 0.625 | Q22: =if(O22-N22 < 0 , (O22-N22+1)*24, (O22-N22)*24) -> 8.5 | R22: 강순옥 | S22: 0.27083333 | T22: 0.625 | V22: =if(T22-S22 < 0 , (T22-S22+1)*24, (T22-S22)*24) -> 8.5 | W22: 강순옥 | X22: 0.27083333 | Y22: 0.625 | AA22: =if(Y22-X22 < 0 , (Y22-X22+1)*24, (Y22-X22)*24) -> 8.5 | AB22: 알리사 | AC22: 0.30208333 | AD22: 0.51041667 | AF22: =if(AD22-AC22 < 0 , (AD22-AC22+1)*24, (AD22-AC22)*24) -> 5 | AG22: 최제일 | AH22: 0.30208333 | AI22: 0.51041667 | AK22: =if(AI22-AH22 < 0 , (AI22-AH22+1)*24, (AI22-AH22)*24) -> 5
A23: 4주차 | B23: 2 | C23: 배은솔 | D23: 0.625 | E23: 0.77083333 | G23: =if(E23-D23 < 0 , (E23-D23+1)*24, (E23-D23)*24) -> 3.5 | H23: 김현지 | I23: 0.625 | J23: 0.77083333 | L23: =if(J23-I23 < 0 , (J23-I23+1)*24, (J23-I23)*24) -> 3.5 | M23: 안지혜 | N23: 0.625 | O23: 0.79166667 | Q23: =if(O23-N23 < 0 , (O23-N23+1)*24, (O23-N23)*24) -> 4 | R23: 김현지 | S23: 0.625 | T23: 0.77083333 | V23: =if(T23-S23 < 0 , (T23-S23+1)*24, (T23-S23)*24) -> 3.5 | W23: 배은솔 | X23: 0.625 | Y23: 0.77083333 | AA23: =if(Y23-X23 < 0 , (Y23-X23+1)*24, (Y23-X23)*24) -> 3.5 | AB23: 안지혜 | AC23: 0.5 | AD23: 0.6875 | AF23: =if(AD23-AC23 < 0 , (AD23-AC23+1)*24, (AD23-AC23)*24) -> 4.5 | AG23: 안지혜 | AH23: 0.5 | AI23: 0.66666667 | AK23: =if(AI23-AH23 < 0 , (AI23-AH23+1)*24, (AI23-AH23)*24) -> 4
A24: 4주차 | B24: 3 | C24: 문병준 | D24: 0.77083333 | E24: 0.95833333 | G24: =if(E24-D24 < 0 , (E24-D24+1)*24, (E24-D24)*24) -> 4.5 | H24: 알리사 | I24: 0.77083333 | J24: 0.95833333 | L24: =if(J24-I24 < 0 , (J24-I24+1)*24, (J24-I24)*24) -> 4.5 | M24: 문병준 | N24: 0.77083333 | O24: 0.95833333 | Q24: =if(O24-N24 < 0 , (O24-N24+1)*24, (O24-N24)*24) -> 4.5 | R24: 알리사 | S24: 0.77083333 | T24: 0.95833333 | V24: =if(T24-S24 < 0 , (T24-S24+1)*24, (T24-S24)*24) -> 4.5 | W24: 문병준 | X24: 0.77083333 | Y24: 0.95833333 | AA24: =if(Y24-X24 < 0 , (Y24-X24+1)*24, (Y24-X24)*24) -> 4.5 | AB24: 김현지 | AC24: 0.66666667 | AD24: 0.95833333 | AF24: =if(AD24-AC24 < 0 , (AD24-AC24+1)*24, (AD24-AC24)*24) -> 7 | AG24: 김현지 | AH24: 0.66666667 | AI24: 0.95833333 | AK24: =if(AI24-AH24 < 0 , (AI24-AH24+1)*24, (AI24-AH24)*24) -> 7
A25: 4주차 | B25: 4 | C25: 김석원 | D25: 0.91666667 | E25: 0.27083333 | G25: =if(E25-D25 < 0 , (E25-D25+1)*24, (E25-D25)*24) -> 8.5 | H25: 김석원 | I25: 0.91666667 | J25: 0.27083333 | L25: =if(J25-I25 < 0 , (J25-I25+1)*24, (J25-I25)*24) -> 8.5 | M25: 김석원 | N25: 0.91666667 | O25: 0.27083333 | Q25: =if(O25-N25 < 0 , (O25-N25+1)*24, (O25-N25)*24) -> 8.5 | R25: 김석원 | S25: 0.91666667 | T25: 0.27083333 | V25: =if(T25-S25 < 0 , (T25-S25+1)*24, (T25-S25)*24) -> 8.5 | W25: 이주형 | X25: 0.91666667 | Y25: 0.30208333 | AA25: =if(Y25-X25 < 0 , (Y25-X25+1)*24, (Y25-X25)*24) -> 9.25 | AB25: 이주형 | AC25: 0.94791667 | AD25: 0.30208333 | AF25: =if(AD25-AC25 < 0 , (AD25-AC25+1)*24, (AD25-AC25)*24) -> 8.5 | AG25: 김석원 | AH25: 0.95833333 | AI25: 0.29166667 | AK25: =if(AI25-AH25 < 0 , (AI25-AH25+1)*24, (AI25-AH25)*24) -> 8
A26: 4주차 | B26: 5 | G26: =if(E26-D26 < 0 , (E26-D26+1)*24, (E26-D26)*24) -> 0 | L26: =if(J26-I26 < 0 , (J26-I26+1)*24, (J26-I26)*24) -> 0 | Q26: =if(O26-N26 < 0 , (O26-N26+1)*24, (O26-N26)*24) -> 0 | V26: =if(T26-S26 < 0 , (T26-S26+1)*24, (T26-S26)*24) -> 0 | AA26: =if(Y26-X26 < 0 , (Y26-X26+1)*24, (Y26-X26)*24) -> 0 | AF26: =if(AD26-AC26 < 0 , (AD26-AC26+1)*24, (AD26-AC26)*24) -> 0 | AK26: =if(AI26-AH26 < 0 , (AI26-AH26+1)*24, (AI26-AH26)*24) -> 0
B27: 일자 | C27: 29 | G27: =if(E27-D27 < 0 , (E27-D27+1)*24, (E27-D27)*24) -> 0 | H27: 30 | L27: =if(J27-I27 < 0 , (J27-I27+1)*24, (J27-I27)*24) -> 0 | Q27: =if(O27-N27 < 0 , (O27-N27+1)*24, (O27-N27)*24) -> 0 | V27: =if(T27-S27 < 0 , (T27-S27+1)*24, (T27-S27)*24) -> 0 | AA27: =if(Y27-X27 < 0 , (Y27-X27+1)*24, (Y27-X27)*24) -> 0 | AF27: =if(AD27-AC27 < 0 , (AD27-AC27+1)*24, (AD27-AC27)*24) -> 0 | AK27: =if(AI27-AH27 < 0 , (AI27-AH27+1)*24, (AI27-AH27)*24) -> 0
A28: 5주차 | B28: 1 | C28: 강순옥 | D28: 0.27083333 | E28: 0.625 | G28: =if(E28-D28 < 0 , (E28-D28+1)*24, (E28-D28)*24) -> 8.5 | H28: 강순옥 | I28: 0.27083333 | J28: 0.625 | L28: =if(J28-I28 < 0 , (J28-I28+1)*24, (J28-I28)*24) -> 8.5 | Q28: =if(O28-N28 < 0 , (O28-N28+1)*24, (O28-N28)*24) -> 0 | V28: =if(T28-S28 < 0 , (T28-S28+1)*24, (T28-S28)*24) -> 0 | AA28: =if(Y28-X28 < 0 , (Y28-X28+1)*24, (Y28-X28)*24) -> 0 | AF28: =if(AD28-AC28 < 0 , (AD28-AC28+1)*24, (AD28-AC28)*24) -> 0 | AK28: =if(AI28-AH28 < 0 , (AI28-AH28+1)*24, (AI28-AH28)*24) -> 0
A29: 5주차 | B29: 2 | C29: 배은솔 | D29: 0.625 | E29: 0.77083333 | G29: =if(E29-D29 < 0 , (E29-D29+1)*24, (E29-D29)*24) -> 3.5 | H29: 김현지 | I29: 0.625 | J29: 0.77083333 | L29: =if(J29-I29 < 0 , (J29-I29+1)*24, (J29-I29)*24) -> 3.5 | Q29: =if(O29-N29 < 0 , (O29-N29+1)*24, (O29-N29)*24) -> 0 | V29: =if(T29-S29 < 0 , (T29-S29+1)*24, (T29-S29)*24) -> 0 | AA29: =if(Y29-X29 < 0 , (Y29-X29+1)*24, (Y29-X29)*24) -> 0 | AF29: =if(AD29-AC29 < 0 , (AD29-AC29+1)*24, (AD29-AC29)*24) -> 0 | AK29: =if(AI29-AH29 < 0 , (AI29-AH29+1)*24, (AI29-AH29)*24) -> 0
A30: 5주차 | B30: 3 | C30: 문병준 | D30: 0.77083333 | E30: 0.95833333 | G30: =if(E30-D30 < 0 , (E30-D30+1)*24, (E30-D30)*24) -> 4.5 | H30: 알리사 | I30: 0.77083333 | J30: 0.95833333 | L30: =if(J30-I30 < 0 , (J30-I30+1)*24, (J30-I30)*24) -> 4.5 | Q30: =if(O30-N30 < 0 , (O30-N30+1)*24, (O30-N30)*24) -> 0 | V30: =if(T30-S30 < 0 , (T30-S30+1)*24, (T30-S30)*24) -> 0 | AA30: =if(Y30-X30 < 0 , (Y30-X30+1)*24, (Y30-X30)*24) -> 0 | AF30: =if(AD30-AC30 < 0 , (AD30-AC30+1)*24, (AD30-AC30)*24) -> 0 | AK30: =if(AI30-AH30 < 0 , (AI30-AH30+1)*24, (AI30-AH30)*24) -> 0
A31: 5주차 | B31: 4 | C31: 김석원 | D31: 0.91666667 | E31: 0.27083333 | G31: =if(E31-D31 < 0 , (E31-D31+1)*24, (E31-D31)*24) -> 8.5 | H31: 김석원 | I31: 0.91666667 | J31: 0.27083333 | L31: =if(J31-I31 < 0 , (J31-I31+1)*24, (J31-I31)*24) -> 8.5 | Q31: =if(O31-N31 < 0 , (O31-N31+1)*24, (O31-N31)*24) -> 0 | V31: =if(T31-S31 < 0 , (T31-S31+1)*24, (T31-S31)*24) -> 0 | AA31: =if(Y31-X31 < 0 , (Y31-X31+1)*24, (Y31-X31)*24) -> 0 | AF31: =if(AD31-AC31 < 0 , (AD31-AC31+1)*24, (AD31-AC31)*24) -> 0 | AK31: =if(AI31-AH31 < 0 , (AI31-AH31+1)*24, (AI31-AH31)*24) -> 0
A32: 5주차 | B32: 5 | G32: =if(E32-D32 < 0 , (E32-D32+1)*24, (E32-D32)*24) -> 0 | L32: =if(J32-I32 < 0 , (J32-I32+1)*24, (J32-I32)*24) -> 0 | Q32: =if(O32-N32 < 0 , (O32-N32+1)*24, (O32-N32)*24) -> 0 | V32: =if(T32-S32 < 0 , (T32-S32+1)*24, (T32-S32)*24) -> 0 | AA32: =if(Y32-X32 < 0 , (Y32-X32+1)*24, (Y32-X32)*24) -> 0 | AF32: =if(AD32-AC32 < 0 , (AD32-AC32+1)*24, (AD32-AC32)*24) -> 0 | AK32: =if(AI32-AH32 < 0 , (AI32-AH32+1)*24, (AI32-AH32)*24) -> 0
B33: 일자 | G33: =if(E33-D33 < 0 , (E33-D33+1)*24, (E33-D33)*24) -> 0 | L33: =if(J33-I33 < 0 , (J33-I33+1)*24, (J33-I33)*24) -> 0 | Q33: =if(O33-N33 < 0 , (O33-N33+1)*24, (O33-N33)*24) -> 0 | V33: =if(T33-S33 < 0 , (T33-S33+1)*24, (T33-S33)*24) -> 0 | AA33: =if(Y33-X33 < 0 , (Y33-X33+1)*24, (Y33-X33)*24) -> 0 | AF33: =if(AD33-AC33 < 0 , (AD33-AC33+1)*24, (AD33-AC33)*24) -> 0 | AK33: =if(AI33-AH33 < 0 , (AI33-AH33+1)*24, (AI33-AH33)*24) -> 0
A34: 6주차 | B34: 1 | G34: =if(E34-D34 < 0 , (E34-D34+1)*24, (E34-D34)*24) -> 0 | L34: =if(J34-I34 < 0 , (J34-I34+1)*24, (J34-I34)*24) -> 0 | Q34: =if(O34-N34 < 0 , (O34-N34+1)*24, (O34-N34)*24) -> 0 | V34: =if(T34-S34 < 0 , (T34-S34+1)*24, (T34-S34)*24) -> 0 | AA34: =if(Y34-X34 < 0 , (Y34-X34+1)*24, (Y34-X34)*24) -> 0 | AF34: =if(AD34-AC34 < 0 , (AD34-AC34+1)*24, (AD34-AC34)*24) -> 0 | AK34: =if(AI34-AH34 < 0 , (AI34-AH34+1)*24, (AI34-AH34)*24) -> 0
A35: 6주차 | B35: 2 | G35: =if(E35-D35 < 0 , (E35-D35+1)*24, (E35-D35)*24) -> 0 | L35: =if(J35-I35 < 0 , (J35-I35+1)*24, (J35-I35)*24) -> 0 | Q35: =if(O35-N35 < 0 , (O35-N35+1)*24, (O35-N35)*24) -> 0 | V35: =if(T35-S35 < 0 , (T35-S35+1)*24, (T35-S35)*24) -> 0 | AA35: =if(Y35-X35 < 0 , (Y35-X35+1)*24, (Y35-X35)*24) -> 0 | AF35: =if(AD35-AC35 < 0 , (AD35-AC35+1)*24, (AD35-AC35)*24) -> 0 | AK35: =if(AI35-AH35 < 0 , (AI35-AH35+1)*24, (AI35-AH35)*24) -> 0
A36: 6주차 | B36: 3 | G36: =if(E36-D36 < 0 , (E36-D36+1)*24, (E36-D36)*24) -> 0 | L36: =if(J36-I36 < 0 , (J36-I36+1)*24, (J36-I36)*24) -> 0 | Q36: =if(O36-N36 < 0 , (O36-N36+1)*24, (O36-N36)*24) -> 0 | V36: =if(T36-S36 < 0 , (T36-S36+1)*24, (T36-S36)*24) -> 0 | AA36: =if(Y36-X36 < 0 , (Y36-X36+1)*24, (Y36-X36)*24) -> 0 | AF36: =if(AD36-AC36 < 0 , (AD36-AC36+1)*24, (AD36-AC36)*24) -> 0 | AK36: =if(AI36-AH36 < 0 , (AI36-AH36+1)*24, (AI36-AH36)*24) -> 0
A37: 6주차 | B37: 4 | G37: =if(E37-D37 < 0 , (E37-D37+1)*24, (E37-D37)*24) -> 0 | L37: =if(J37-I37 < 0 , (J37-I37+1)*24, (J37-I37)*24) -> 0 | Q37: =if(O37-N37 < 0 , (O37-N37+1)*24, (O37-N37)*24) -> 0 | V37: =if(T37-S37 < 0 , (T37-S37+1)*24, (T37-S37)*24) -> 0 | AA37: =if(Y37-X37 < 0 , (Y37-X37+1)*24, (Y37-X37)*24) -> 0 | AF37: =if(AD37-AC37 < 0 , (AD37-AC37+1)*24, (AD37-AC37)*24) -> 0 | AK37: =if(AI37-AH37 < 0 , (AI37-AH37+1)*24, (AI37-AH37)*24) -> 0
A38: 6주차 | B38: 5 | G38: =if(E38-D38 < 0 , (E38-D38+1)*24, (E38-D38)*24) -> 0 | L38: =if(J38-I38 < 0 , (J38-I38+1)*24, (J38-I38)*24) -> 0 | Q38: =if(O38-N38 < 0 , (O38-N38+1)*24, (O38-N38)*24) -> 0 | V38: =if(T38-S38 < 0 , (T38-S38+1)*24, (T38-S38)*24) -> 0 | AA38: =if(Y38-X38 < 0 , (Y38-X38+1)*24, (Y38-X38)*24) -> 0 | AF38: =if(AD38-AC38 < 0 , (AD38-AC38+1)*24, (AD38-AC38)*24) -> 0 | AK38: =if(AI38-AH38 < 0 , (AI38-AH38+1)*24, (AI38-AH38)*24) -> 0

Sheet 대치 9월 주급여
A1: 주차 | B1: 구분 | C1: 이름 | D1: 근무시간 | E1: 주휴여부 | F1: 시급 | G1: 급여 | H1: 주휴수당 | I1: 주급 | J1: 비고 | L1: 구분 | M1: 이름 | N1: 총 근무시간 | O1: 급여 합 | P1: 주휴수당 합 | Q1: 월급 | R1: 근로소득세(3.3%) | S1: 지급액 | T1: 비고
A2: 1주차 | B2: 1 | C2: 강순옥 | D2: =sumifs('대치메가 9월 급여'!$G:$G, '대치메가 9월 급여'!$C:$C, C2, '대치메가 9월 급여'!$A:$A, A2) + sumifs('대치메가 9월 급여'!$L:$L,'대치메가 9월 급여'!$H:$H,C2, '대치메가 9월 급여'!$A:$A, A2) + sumifs('대치메가 9월 급여'!$Q:$Q,'대치메가 9월 급여'!$M:$M,C2, '대치메가 9월 급여'!$A:$A, A2) + sumifs('대치메가 9월 급여'!$V:$V,'대치메가 9월 급여'!$R:$R,C2, '대치메가 9월 급여'!$A:$A, A2) + sumifs('대치메가 9월 급여'!$AA:$AA,'대치메가 9월 급여'!$W:$W,C2, '대치메가 9월 급여'!$A:$A, A2) + sumifs('대치메가 9월 급여'!$AF:$AF,'대치메가 9월 급여'!$AB:$AB,C2, '대치메가 9월 급여'!$A:$A, A2) + sumifs('대치메가 9월 급여'!$AK:$AK,'대치메가 9월 급여'!$AG:$AG,C2, '대치메가 9월 급여'!$A:$A, A2) -> 42.5 | E2: =if(D2 >= 15, "O", "X") -> O | F2: 10030 | G2: =D2*F2 -> 426275 | H2: =if(E2="O", D2/40*8*F2, 0) -> 85255 | I2: =sum(G2:H2) -> 511530 | L2: 1 | M2: 강순옥 | N2: =sumif($C:$C, M2, $D:$D) -> 188 | O2: =sumif($C:$C, M2, $G:$G) -> 1885640 | P2: =sumif($C:$C, M2, $H:$H) -> 377128 | Q2: =sum(O2:P2) -> 2262768 | R2: 0 | S2: =Q2-R2 -> 2262768
A3: 1주차 | B3: 2 | C3: 배은솔 | D3: =sumifs('대치메가 9월 급여'!$G:$G, '대치메가 9월 급여'!$C:$C, C3, '대치메가 9월 급여'!$A:$A, A3) + sumifs('대치메가 9월 급여'!$L:$L,'대치메가 9월 급여'!$H:$H,C3, '대치메가 9월 급여'!$A:$A, A3) + sumifs('대치메가 9월 급여'!$Q:$Q,'대치메가 9월 급여'!$M:$M,C3, '대치메가 9월 급여'!$A:$A, A3) + sumifs('대치메가 9월 급여'!$V:$V,'대치메가 9월 급여'!$R:$R,C3, '대치메가 9월 급여'!$A:$A, A3) + sumifs('대치메가 9월 급여'!$AA:$AA,'대치메가 9월 급여'!$W:$W,C3, '대치메가 9월 급여'!$A:$A, A3) + sumifs('대치메가 9월 급여'!$AF:$AF,'대치메가 9월 급여'!$AB:$AB,C3, '대치메가 9월 급여'!$A:$A, A3) + sumifs('대치메가 9월 급여'!$AK:$AK,'대치메가 9월 급여'!$AG:$AG,C3, '대치메가 9월 급여'!$A:$A, A3) -> 7 | E3: =if(D3 >= 15, "O", "X") -> X | F3: 10030 | G3: =D3*F3 -> 70210 | H3: =if(E3="O", D3/40*8*F3, 0) -> 0 | I3: =sum(G3:H3) -> 70210 | L3: 2 | M3: 배은솔 | N3: =sumif($C:$C, M3, $D:$D) -> 31.5 | O3: =sumif($C:$C, M3, $G:$G) -> 315945 | P3: =sumif($C:$C, M3, $H:$H) -> 0 | Q3: =sum(O3:P3) -> 315945 | R3: 0 | S3: =Q3-R3 -> 315945
A4: 1주차 | B4: 3 | C4: 김석원 | D4: =sumifs('대치메가 9월 급여'!$G:$G, '대치메가 9월 급여'!$C:$C, C4, '대치메가 9월 급여'!$A:$A, A4) + sumifs('대치메가 9월 급여'!$L:$L,'대치메가 9월 급여'!$H:$H,C4, '대치메가 9월 급여'!$A:$A, A4) + sumifs('대치메가 9월 급여'!$Q:$Q,'대치메가 9월 급여'!$M:$M,C4, '대치메가 9월 급여'!$A:$A, A4) + sumifs('대치메가 9월 급여'!$V:$V,'대치메가 9월 급여'!$R:$R,C4, '대치메가 9월 급여'!$A:$A, A4) + sumifs('대치메가 9월 급여'!$AA:$AA,'대치메가 9월 급여'!$W:$W,C4, '대치메가 9월 급여'!$A:$A, A4) + sumifs('대치메가 9월 급여'!$AF:$AF,'대치메가 9월 급여'!$AB:$AB,C4, '대치메가 9월 급여'!$A:$A, A4) + sumifs('대치메가 9월 급여'!$AK:$AK,'대치메가 9월 급여'!$AG:$AG,C4, '대치메가 9월 급여'!$A:$A, A4) -> 42 | E4: =if(D4 >= 15, "O", "X") -> O | F4: 11030 | G4: =D4*F4 -> 463260 | H4: =if(E4="O", 40/40*8*F4, 0) -> 88240 | I4: =sum(G4:H4) -> 551500 | L4: 3 | M4: 김석원 | N4: =sumif($C:$C, M4, $D:$D) -> 185 | O4: =sumif($C:$C, M4, $G:$G) -> 2040550 | P4: =sumif($C:$C, M4, $H:$H) -> 352960 | Q4: =sum(O4:P4) -> 2393510 | R4: =trunc(Q4*3%,-1)+trunc((Q4*3%)/10, -1) -> 78980 | S4: =Q4-R4 -> 2314530
A5: 1주차 | B5: 4 | C5: 김현지 | D5: =sumifs('대치메가 9월 급여'!$G:$G, '대치메가 9월 급여'!$C:$C, C5, '대치메가 9월 급여'!$A:$A, A5) + sumifs('대치메가 9월 급여'!$L:$L,'대치메가 9월 급여'!$H:$H,C5, '대치메가 9월 급여'!$A:$A, A5) + sumifs('대치메가 9월 급여'!$Q:$Q,'대치메가 9월 급여'!$M:$M,C5, '대치메가 9월 급여'!$A:$A, A5) + sumifs('대치메가 9월 급여'!$V:$V,'대치메가 9월 급여'!$R:$R,C5, '대치메가 9월 급여'!$A:$A, A5) + sumifs('대치메가 9월 급여'!$AA:$AA,'대치메가 9월 급여'!$W:$W,C5, '대치메가 9월 급여'!$A:$A, A5) + sumifs('대치메가 9월 급여'!$AF:$AF,'대치메가 9월 급여'!$AB:$AB,C5, '대치메가 9월 급여'!$A:$A, A5) + sumifs('대치메가 9월 급여'!$AK:$AK,'대치메가 9월 급여'!$AG:$AG,C5, '대치메가 9월 급여'!$A:$A, A5) -> 20.5 | E5: =if(D5 >= 15, "O", "X") -> O | F5: 10030 | G5: =D5*F5 -> 205615 | H5: =if(E5="O", 21/40*8*F5, 0) -> 42126 | I5: =sum(G5:H5) -> 247741 | L5: 4 | M5: 김현지 | N5: =sumif($C:$C, M5, $D:$D) -> 87 | O5: =sumif($C:$C, M5, $G:$G) -> 872610 | P5: =sumif($C:$C, M5, $H:$H) -> 168504 | Q5: =sum(O5:P5) -> 1041114 | R5: =trunc(Q5*3%,-1)+trunc((Q5*3%)/10, -1) -> 34350 | S5: =Q5-R5 -> 1006764 | U5: 김수옥 | V5: 3.3% 사업소득신고
A6: 1주차 | B6: 5 | C6: 문병준 | D6: =sumifs('대치메가 9월 급여'!$G:$G, '대치메가 9월 급여'!$C:$C, C6, '대치메가 9월 급여'!$A:$A, A6) + sumifs('대치메가 9월 급여'!$L:$L,'대치메가 9월 급여'!$H:$H,C6, '대치메가 9월 급여'!$A:$A, A6) + sumifs('대치메가 9월 급여'!$Q:$Q,'대치메가 9월 급여'!$M:$M,C6, '대치메가 9월 급여'!$A:$A, A6) + sumifs('대치메가 9월 급여'!$V:$V,'대치메가 9월 급여'!$R:$R,C6, '대치메가 9월 급여'!$A:$A, A6) + sumifs('대치메가 9월 급여'!$AA:$AA,'대치메가 9월 급여'!$W:$W,C6, '대치메가 9월 급여'!$A:$A, A6) + sumifs('대치메가 9월 급여'!$AF:$AF,'대치메가 9월 급여'!$AB:$AB,C6, '대치메가 9월 급여'!$A:$A, A6) + sumifs('대치메가 9월 급여'!$AK:$AK,'대치메가 9월 급여'!$AG:$AG,C6, '대치메가 9월 급여'!$A:$A, A6) -> 12.5 | E6: X | F6: 11030 | G6: =D6*F6 -> 137875 | H6: =if(E6="O", D6/40*8*F6, 0) -> 0 | I6: =sum(G6:H6) -> 137875 | L6: 5 | M6: 문병준 | N6: =sumif($C:$C, M6, $D:$D) -> 63 | O6: =sumif($C:$C, M6, $G:$G) -> 694890 | P6: =sumif($C:$C, M6, $H:$H) -> 0 | Q6: =sum(O6:P6) -> 694890 | R6: 0 | S6: =Q6-R6 -> 694890 | U6: 김현지 | V6: 3.3% 사업소득신고
A7: 1주차 | B7: 6 | C7: 안지혜 | D7: =sumifs('대치메가 9월 급여'!$G:$G, '대치메가 9월 급여'!$C:$C, C7, '대치메가 9월 급여'!$A:$A, A7) + sumifs('대치메가 9월 급여'!$L:$L,'대치메가 9월 급여'!$H:$H,C7, '대치메가 9월 급여'!$A:$A, A7) + sumifs('대치메가 9월 급여'!$Q:$Q,'대치메가 9월 급여'!$M:$M,C7, '대치메가 9월 급여'!$A:$A, A7) + sumifs('대치메가 9월 급여'!$V:$V,'대치메가 9월 급여'!$R:$R,C7, '대치메가 9월 급여'!$A:$A, A7) + sumifs('대치메가 9월 급여'!$AA:$AA,'대치메가 9월 급여'!$W:$W,C7, '대치메가 9월 급여'!$A:$A, A7) + sumifs('대치메가 9월 급여'!$AF:$AF,'대치메가 9월 급여'!$AB:$AB,C7, '대치메가 9월 급여'!$A:$A, A7) + sumifs('대치메가 9월 급여'!$AK:$AK,'대치메가 9월 급여'!$AG:$AG,C7, '대치메가 9월 급여'!$A:$A, A7) -> 9 | E7: =if(D7 >= 15, "O", "X") -> X | F7: 11030 | G7: =D7*F7 -> 99270 | H7: =if(E7="O", D7/40*8*F7, 0) -> 0 | I7: =sum(G7:H7) -> 99270 | L7: 6 | M7: 안지혜 | N7: =sumif($C:$C, M7, $D:$D) -> 38.5 | O7: =sumif($C:$C, M7, $G:$G) -> 424655 | P7: =sumif($C:$C, M7, $H:$H) -> 0 | Q7: =sum(O7:P7) -> 424655 | R7: 0 | S7: =Q7-R7 -> 424655 | U7: 문병준 | V7: 주15시간 미만
A8: 1주차 | B8: 7 | C8: 알리사 | D8: =sumifs('대치메가 9월 급여'!$G:$G, '대치메가 9월 급여'!$C:$C, C8, '대치메가 9월 급여'!$A:$A, A8) + sumifs('대치메가 9월 급여'!$L:$L,'대치메가 9월 급여'!$H:$H,C8, '대치메가 9월 급여'!$A:$A, A8) + sumifs('대치메가 9월 급여'!$Q:$Q,'대치메가 9월 급여'!$M:$M,C8, '대치메가 9월 급여'!$A:$A, A8) + sumifs('대치메가 9월 급여'!$V:$V,'대치메가 9월 급여'!$R:$R,C8, '대치메가 9월 급여'!$A:$A, A8) + sumifs('대치메가 9월 급여'!$AA:$AA,'대치메가 9월 급여'!$W:$W,C8, '대치메가 9월 급여'!$A:$A, A8) + sumifs('대치메가 9월 급여'!$AF:$AF,'대치메가 9월 급여'!$AB:$AB,C8, '대치메가 9월 급여'!$A:$A, A8) + sumifs('대치메가 9월 급여'!$AK:$AK,'대치메가 9월 급여'!$AG:$AG,C8, '대치메가 9월 급여'!$A:$A, A8) -> 19 | E8: =if(D8 >= 15, "O", "X") -> O | F8: 10030 | G8: =D8*F8 -> 190570 | H8: =if(E8="O", D8/40*8*F8, 0) -> 38114 | I8: =sum(G8:H8) -> 228684 | L8: 7 | M8: 알리사 | N8: =sumif($C:$C, M8, $D:$D) -> 75.5 | O8: =sumif($C:$C, M8, $G:$G) -> 757265 | P8: =sumif($C:$C, M8, $H:$H) -> 114342 | Q8: =sum(O8:P8) -> 871607 | R8: =trunc(Q8*3%,-1)+trunc((Q8*3%)/10, -1) -> 28750 | S8: =Q8-R8 -> 842857 | U8: 알리사 | V8: 주15시간 미만
A9: 1주차 | B9: 8 | C9: 이주형 | D9: =sumifs('대치메가 9월 급여'!$G:$G, '대치메가 9월 급여'!$C:$C, C9, '대치메가 9월 급여'!$A:$A, A9) + sumifs('대치메가 9월 급여'!$L:$L,'대치메가 9월 급여'!$H:$H,C9, '대치메가 9월 급여'!$A:$A, A9) + sumifs('대치메가 9월 급여'!$Q:$Q,'대치메가 9월 급여'!$M:$M,C9, '대치메가 9월 급여'!$A:$A, A9) + sumifs('대치메가 9월 급여'!$V:$V,'대치메가 9월 급여'!$R:$R,C9, '대치메가 9월 급여'!$A:$A, A9) + sumifs('대치메가 9월 급여'!$AA:$AA,'대치메가 9월 급여'!$W:$W,C9, '대치메가 9월 급여'!$A:$A, A9) + sumifs('대치메가 9월 급여'!$AF:$AF,'대치메가 9월 급여'!$AB:$AB,C9, '대치메가 9월 급여'!$A:$A, A9) + sumifs('대치메가 9월 급여'!$AK:$AK,'대치메가 9월 급여'!$AG:$AG,C9, '대치메가 9월 급여'!$A:$A, A9) -> 17.75 | E9: =if(D9 >= 15, "O", "X") -> O | F9: 11030 | G9: =D9*F9 -> 195782.5 | H9: =if(E9="O", 17/40*8*F9, 0) -> 37502 | I9: =sum(G9:H9) -> 233284.5 | L9: 8 | M9: 이주형 | N9: =sumif($C:$C, M9, $D:$D) -> 71 | O9: =sumif($C:$C, M9, $G:$G) -> 783130 | P9: =sumif($C:$C, M9, $H:$H) -> 150008 | Q9: =sum(O9:P9) -> 933138 | R9: =trunc(Q9*3%,-1)+trunc((Q9*3%)/10, -1) -> 30780 | S9: =Q9-R9 -> 902358 | U9: 오수진 | V9: 주15시간 미만
A10: 1주차 | B10: 9 | C10: 최제일 | D10: =sumifs('대치메가 9월 급여'!$G:$G, '대치메가 9월 급여'!$C:$C, C10, '대치메가 9월 급여'!$A:$A, A10) + sumifs('대치메가 9월 급여'!$L:$L,'대치메가 9월 급여'!$H:$H,C10, '대치메가 9월 급여'!$A:$A, A10) + sumifs('대치메가 9월 급여'!$Q:$Q,'대치메가 9월 급여'!$M:$M,C10, '대치메가 9월 급여'!$A:$A, A10) + sumifs('대치메가 9월 급여'!$V:$V,'대치메가 9월 급여'!$R:$R,C10, '대치메가 9월 급여'!$A:$A, A10) + sumifs('대치메가 9월 급여'!$AA:$AA,'대치메가 9월 급여'!$W:$W,C10, '대치메가 9월 급여'!$A:$A, A10) + sumifs('대치메가 9월 급여'!$AF:$AF,'대치메가 9월 급여'!$AB:$AB,C10, '대치메가 9월 급여'!$A:$A, A10) + sumifs('대치메가 9월 급여'!$AK:$AK,'대치메가 9월 급여'!$AG:$AG,C10, '대치메가 9월 급여'!$A:$A, A10) -> 4.5 | E10: =if(D10 >= 15, "O", "X") -> X | F10: 10030 | G10: =D10*F10 -> 45135 | H10: =if(E10="O", D10/40*8*F10, 0) -> 0 | I10: =sum(G10:H10) -> 45135 | L10: 9 | M10: 최제일 | N10: =sumif($C:$C, M10, $D:$D) -> 9.5 | O10: =sumif($C:$C, M10, $G:$G) -> 95285 | P10: =sumif($C:$C, M10, $H:$H) -> 0 | Q10: =sum(O10:P10) -> 95285 | R10: 0 | S10: =Q10-R10 -> 95285 | T10: 삼성근무 | U10: 윤예원 | V10: 주15시간 미만
A11: 1주차 | B11: 10 | D11: =sumifs('대치메가 9월 급여'!$G:$G, '대치메가 9월 급여'!$C:$C, C11, '대치메가 9월 급여'!$A:$A, A11) + sumifs('대치메가 9월 급여'!$L:$L,'대치메가 9월 급여'!$H:$H,C11, '대치메가 9월 급여'!$A:$A, A11) + sumifs('대치메가 9월 급여'!$Q:$Q,'대치메가 9월 급여'!$M:$M,C11, '대치메가 9월 급여'!$A:$A, A11) + sumifs('대치메가 9월 급여'!$V:$V,'대치메가 9월 급여'!$R:$R,C11, '대치메가 9월 급여'!$A:$A, A11) + sumifs('대치메가 9월 급여'!$AA:$AA,'대치메가 9월 급여'!$W:$W,C11, '대치메가 9월 급여'!$A:$A, A11) + sumifs('대치메가 9월 급여'!$AF:$AF,'대치메가 9월 급여'!$AB:$AB,C11, '대치메가 9월 급여'!$A:$A, A11) + sumifs('대치메가 9월 급여'!$AK:$AK,'대치메가 9월 급여'!$AG:$AG,C11, '대치메가 9월 급여'!$A:$A, A11) -> 0 | E11: =if(D11 >= 15, "O", "X") -> X | F11: 10030 | G11: =D11*F11 -> 0 | H11: =if(E11="O", D11/40*8*F11, 0) -> 0 | I11: =sum(G11:H11) -> 0 | L11: 10 | N11: =sumif($C:$C, M11, $D:$D) -> 0 | O11: =sumif($C:$C, M11, $G:$G) -> 0 | P11: =sumif($C:$C, M11, $H:$H) -> 0 | Q11: =sum(O11:P11) -> 0 | R11: 0 | S11: =Q11-R11 -> 0 | U11: 박소혜 | V11: 3.3% 사업소득신고
A12: 1주차 | B12: 11 | D12: =sumifs('대치메가 9월 급여'!$G:$G, '대치메가 9월 급여'!$C:$C, C12, '대치메가 9월 급여'!$A:$A, A12) + sumifs('대치메가 9월 급여'!$L:$L,'대치메가 9월 급여'!$H:$H,C12, '대치메가 9월 급여'!$A:$A, A12) + sumifs('대치메가 9월 급여'!$Q:$Q,'대치메가 9월 급여'!$M:$M,C12, '대치메가 9월 급여'!$A:$A, A12) + sumifs('대치메가 9월 급여'!$V:$V,'대치메가 9월 급여'!$R:$R,C12, '대치메가 9월 급여'!$A:$A, A12) + sumifs('대치메가 9월 급여'!$AA:$AA,'대치메가 9월 급여'!$W:$W,C12, '대치메가 9월 급여'!$A:$A, A12) + sumifs('대치메가 9월 급여'!$AF:$AF,'대치메가 9월 급여'!$AB:$AB,C12, '대치메가 9월 급여'!$A:$A, A12) + sumifs('대치메가 9월 급여'!$AK:$AK,'대치메가 9월 급여'!$AG:$AG,C12, '대치메가 9월 급여'!$A:$A, A12) -> 0 | E12: =if(D12 >= 15, "O", "X") -> X | F12: 10030 | G12: =D12*F12 -> 0 | H12: =if(E12="O", D12/40*8*F12, 0) -> 0 | I12: =sum(G12:H12) -> 0 | L12: 11 | N12: =sumif($C:$C, M12, $D:$D) -> 0 | O12: =sumif($C:$C, M12, $G:$G) -> 0 | P12: =sumif($C:$C, M12, $H:$H) -> 0 | Q12: =sum(O12:P12) -> 0 | R12: 0 | S12: =Q12-R12 -> 0
A13: 1주차 | B13: 12 | D13: =sumifs('대치메가 9월 급여'!$G:$G, '대치메가 9월 급여'!$C:$C, C13, '대치메가 9월 급여'!$A:$A, A13) + sumifs('대치메가 9월 급여'!$L:$L,'대치메가 9월 급여'!$H:$H,C13, '대치메가 9월 급여'!$A:$A, A13) + sumifs('대치메가 9월 급여'!$Q:$Q,'대치메가 9월 급여'!$M:$M,C13, '대치메가 9월 급여'!$A:$A, A13) + sumifs('대치메가 9월 급여'!$V:$V,'대치메가 9월 급여'!$R:$R,C13, '대치메가 9월 급여'!$A:$A, A13) + sumifs('대치메가 9월 급여'!$AA:$AA,'대치메가 9월 급여'!$W:$W,C13, '대치메가 9월 급여'!$A:$A, A13) + sumifs('대치메가 9월 급여'!$AF:$AF,'대치메가 9월 급여'!$AB:$AB,C13, '대치메가 9월 급여'!$A:$A, A13) + sumifs('대치메가 9월 급여'!$AK:$AK,'대치메가 9월 급여'!$AG:$AG,C13, '대치메가 9월 급여'!$A:$A, A13) -> 0 | E13: =if(D13 >= 15, "O", "X") -> X | F13: 10030 | G13: =D13*F13 -> 0 | H13: =if(E13="O", D13/40*8*F13, 0) -> 0 | I13: =sum(G13:H13) -> 0 | L13: 12 | N13: =sumif($C:$C, M13, $D:$D) -> 0 | O13: =sumif($C:$C, M13, $G:$G) -> 0 | P13: =sumif($C:$C, M13, $H:$H) -> 0 | Q13: =sum(O13:P13) -> 0 | R13: =trunc(Q13*3%,-1)+trunc((Q13*3%)/10, -1) -> 0 | S13: =Q13-R13 -> 0
A14: 1주차 | B14: 13 | D14: =sumifs('대치메가 9월 급여'!$G:$G, '대치메가 9월 급여'!$C:$C, C14, '대치메가 9월 급여'!$A:$A, A14) + sumifs('대치메가 9월 급여'!$L:$L,'대치메가 9월 급여'!$H:$H,C14, '대치메가 9월 급여'!$A:$A, A14) + sumifs('대치메가 9월 급여'!$Q:$Q,'대치메가 9월 급여'!$M:$M,C14, '대치메가 9월 급여'!$A:$A, A14) + sumifs('대치메가 9월 급여'!$V:$V,'대치메가 9월 급여'!$R:$R,C14, '대치메가 9월 급여'!$A:$A, A14) + sumifs('대치메가 9월 급여'!$AA:$AA,'대치메가 9월 급여'!$W:$W,C14, '대치메가 9월 급여'!$A:$A, A14) + sumifs('대치메가 9월 급여'!$AF:$AF,'대치메가 9월 급여'!$AB:$AB,C14, '대치메가 9월 급여'!$A:$A, A14) + sumifs('대치메가 9월 급여'!$AK:$AK,'대치메가 9월 급여'!$AG:$AG,C14, '대치메가 9월 급여'!$A:$A, A14) -> 0 | E14: =if(D14 >= 15, "O", "X") -> X | F14: 10030 | G14: =D14*F14 -> 0 | H14: =if(E14="O", D14/40*8*F14, 0) -> 0 | I14: =sum(G14:H14) -> 0 | L14: 13 | N14: =sumif($C:$C, M14, $D:$D) -> 0 | O14: =sumif($C:$C, M14, $G:$G) -> 0 | P14: =sumif($C:$C, M14, $H:$H) -> 0 | Q14: =sum(O14:P14) -> 0 | R14: 0 | S14: =Q14-R14 -> 0 | U14: 서은주 | V14: 3.3% 사업소득신고
A15: 1주차 | B15: 14 | D15: =sumifs('대치메가 9월 급여'!$G:$G, '대치메가 9월 급여'!$C:$C, C15, '대치메가 9월 급여'!$A:$A, A15) + sumifs('대치메가 9월 급여'!$L:$L,'대치메가 9월 급여'!$H:$H,C15, '대치메가 9월 급여'!$A:$A, A15) + sumifs('대치메가 9월 급여'!$Q:$Q,'대치메가 9월 급여'!$M:$M,C15, '대치메가 9월 급여'!$A:$A, A15) + sumifs('대치메가 9월 급여'!$V:$V,'대치메가 9월 급여'!$R:$R,C15, '대치메가 9월 급여'!$A:$A, A15) + sumifs('대치메가 9월 급여'!$AA:$AA,'대치메가 9월 급여'!$W:$W,C15, '대치메가 9월 급여'!$A:$A, A15) + sumifs('대치메가 9월 급여'!$AF:$AF,'대치메가 9월 급여'!$AB:$AB,C15, '대치메가 9월 급여'!$A:$A, A15) + sumifs('대치메가 9월 급여'!$AK:$AK,'대치메가 9월 급여'!$AG:$AG,C15, '대치메가 9월 급여'!$A:$A, A15) -> 0 | E15: =if(D15 >= 15, "O", "X") -> X | F15: 10030 | G15: =D15*F15 -> 0 | H15: =if(E15="O", D15/40*8*F15, 0) -> 0 | I15: =sum(G15:H15) -> 0 | L15: 14 | N15: =sumif($C:$C, M15, $D:$D) -> 0 | O15: =sumif($C:$C, M15, $G:$G) -> 0 | P15: =sumif($C:$C, M15, $H:$H) -> 0 | Q15: =sum(O15:P15) -> 0 | R15: =trunc(Q15*3%,-1)+trunc((Q15*3%)/10, -1) -> 0 | S15: =Q15-R15 -> 0 | U15: 성수진 | V15: 3.3% 사업소득신고
A16: 1주차 | B16: 15 | D16: =sumifs('대치메가 9월 급여'!$G:$G, '대치메가 9월 급여'!$C:$C, C16, '대치메가 9월 급여'!$A:$A, A16) + sumifs('대치메가 9월 급여'!$L:$L,'대치메가 9월 급여'!$H:$H,C16, '대치메가 9월 급여'!$A:$A, A16) + sumifs('대치메가 9월 급여'!$Q:$Q,'대치메가 9월 급여'!$M:$M,C16, '대치메가 9월 급여'!$A:$A, A16) + sumifs('대치메가 9월 급여'!$V:$V,'대치메가 9월 급여'!$R:$R,C16, '대치메가 9월 급여'!$A:$A, A16) + sumifs('대치메가 9월 급여'!$AA:$AA,'대치메가 9월 급여'!$W:$W,C16, '대치메가 9월 급여'!$A:$A, A16) + sumifs('대치메가 9월 급여'!$AF:$AF,'대치메가 9월 급여'!$AB:$AB,C16, '대치메가 9월 급여'!$A:$A, A16) + sumifs('대치메가 9월 급여'!$AK:$AK,'대치메가 9월 급여'!$AG:$AG,C16, '대치메가 9월 급여'!$A:$A, A16) -> 0 | E16: =if(D16 >= 15, "O", "X") -> X | F16: 10030 | G16: =D16*F16 -> 0 | H16: =if(E16="O", D16/40*8*F16, 0) -> 0 | I16: =sum(G16:H16) -> 0 | L16: 15 | N16: =sumif($C:$C, M16, $D:$D) -> 0 | O16: =sumif($C:$C, M16, $G:$G) -> 0 | P16: =sumif($C:$C, M16, $H:$H) -> 0 | Q16: =sum(O16:P16) -> 0 | R16: =trunc(Q16*3%,-1)+trunc((Q16*3%)/10, -1) -> 0 | S16: =Q16-R16 -> 0 | U16: 이성연 | V16: 3.3% 사업소득신고
A17: 2주차 | B17: 1 | C17: 강순옥 | D17: =sumifs('대치메가 9월 급여'!$G:$G, '대치메가 9월 급여'!$C:$C, C17, '대치메가 9월 급여'!$A:$A, A17) + sumifs('대치메가 9월 급여'!$L:$L,'대치메가 9월 급여'!$H:$H,C17, '대치메가 9월 급여'!$A:$A, A17) + sumifs('대치메가 9월 급여'!$Q:$Q,'대치메가 9월 급여'!$M:$M,C17, '대치메가 9월 급여'!$A:$A, A17) + sumifs('대치메가 9월 급여'!$V:$V,'대치메가 9월 급여'!$R:$R,C17, '대치메가 9월 급여'!$A:$A, A17) + sumifs('대치메가 9월 급여'!$AA:$AA,'대치메가 9월 급여'!$W:$W,C17, '대치메가 9월 급여'!$A:$A, A17) + sumifs('대치메가 9월 급여'!$AF:$AF,'대치메가 9월 급여'!$AB:$AB,C17, '대치메가 9월 급여'!$A:$A, A17) + sumifs('대치메가 9월 급여'!$AK:$AK,'대치메가 9월 급여'!$AG:$AG,C17, '대치메가 9월 급여'!$A:$A, A17) -> 43.5 | E17: =if(D17 >= 15, "O", "X") -> O | F17: 10030 | G17: =D17*F17 -> 436305 | H17: =if(E17="O", D17/40*8*F17, 0) -> 87261 | I17: =sum(G17:H17) -> 523566
A18: 2주차 | B18: 2 | C18: 배은솔 | D18: =sumifs('대치메가 9월 급여'!$G:$G, '대치메가 9월 급여'!$C:$C, C18, '대치메가 9월 급여'!$A:$A, A18) + sumifs('대치메가 9월 급여'!$L:$L,'대치메가 9월 급여'!$H:$H,C18, '대치메가 9월 급여'!$A:$A, A18) + sumifs('대치메가 9월 급여'!$Q:$Q,'대치메가 9월 급여'!$M:$M,C18, '대치메가 9월 급여'!$A:$A, A18) + sumifs('대치메가 9월 급여'!$V:$V,'대치메가 9월 급여'!$R:$R,C18, '대치메가 9월 급여'!$A:$A, A18) + sumifs('대치메가 9월 급여'!$AA:$AA,'대치메가 9월 급여'!$W:$W,C18, '대치메가 9월 급여'!$A:$A, A18) + sumifs('대치메가 9월 급여'!$AF:$AF,'대치메가 9월 급여'!$AB:$AB,C18, '대치메가 9월 급여'!$A:$A, A18) + sumifs('대치메가 9월 급여'!$AK:$AK,'대치메가 9월 급여'!$AG:$AG,C18, '대치메가 9월 급여'!$A:$A, A18) -> 7 | E18: =if(D18 >= 15, "O", "X") -> X | F18: 10030 | G18: =D18*F18 -> 70210 | H18: =if(E18="O", D18/40*8*F18, 0) -> 0 | I18: =sum(G18:H18) -> 70210
A19: 2주차 | B19: 3 | C19: 김석원 | D19: =sumifs('대치메가 9월 급여'!$G:$G, '대치메가 9월 급여'!$C:$C, C19, '대치메가 9월 급여'!$A:$A, A19) + sumifs('대치메가 9월 급여'!$L:$L,'대치메가 9월 급여'!$H:$H,C19, '대치메가 9월 급여'!$A:$A, A19) + sumifs('대치메가 9월 급여'!$Q:$Q,'대치메가 9월 급여'!$M:$M,C19, '대치메가 9월 급여'!$A:$A, A19) + sumifs('대치메가 9월 급여'!$V:$V,'대치메가 9월 급여'!$R:$R,C19, '대치메가 9월 급여'!$A:$A, A19) + sumifs('대치메가 9월 급여'!$AA:$AA,'대치메가 9월 급여'!$W:$W,C19, '대치메가 9월 급여'!$A:$A, A19) + sumifs('대치메가 9월 급여'!$AF:$AF,'대치메가 9월 급여'!$AB:$AB,C19, '대치메가 9월 급여'!$A:$A, A19) + sumifs('대치메가 9월 급여'!$AK:$AK,'대치메가 9월 급여'!$AG:$AG,C19, '대치메가 9월 급여'!$A:$A, A19) -> 42 | E19: =if(D19 >= 15, "O", "X") -> O | F19: 11030 | G19: =D19*F19 -> 463260 | H19: =if(E19="O", 40/40*8*F19, 0) -> 88240 | I19: =sum(G19:H19) -> 551500
A20: 2주차 | B20: 4 | C20: 김현지 | D20: =sumifs('대치메가 9월 급여'!$G:$G, '대치메가 9월 급여'!$C:$C, C20, '대치메가 9월 급여'!$A:$A, A20) + sumifs('대치메가 9월 급여'!$L:$L,'대치메가 9월 급여'!$H:$H,C20, '대치메가 9월 급여'!$A:$A, A20) + sumifs('대치메가 9월 급여'!$Q:$Q,'대치메가 9월 급여'!$M:$M,C20, '대치메가 9월 급여'!$A:$A, A20) + sumifs('대치메가 9월 급여'!$V:$V,'대치메가 9월 급여'!$R:$R,C20, '대치메가 9월 급여'!$A:$A, A20) + sumifs('대치메가 9월 급여'!$AA:$AA,'대치메가 9월 급여'!$W:$W,C20, '대치메가 9월 급여'!$A:$A, A20) + sumifs('대치메가 9월 급여'!$AF:$AF,'대치메가 9월 급여'!$AB:$AB,C20, '대치메가 9월 급여'!$A:$A, A20) + sumifs('대치메가 9월 급여'!$AK:$AK,'대치메가 9월 급여'!$AG:$AG,C20, '대치메가 9월 급여'!$A:$A, A20) -> 21 | E20: =if(D20 >= 15, "O", "X") -> O | F20: 10030 | G20: =D20*F20 -> 210630 | H20: =if(E20="O", 21/40*8*F20, 0) -> 42126 | I20: =sum(G20:H20) -> 252756
A21: 2주차 | B21: 5 | C21: 문병준 | D21: =sumifs('대치메가 9월 급여'!$G:$G, '대치메가 9월 급여'!$C:$C, C21, '대치메가 9월 급여'!$A:$A, A21) + sumifs('대치메가 9월 급여'!$L:$L,'대치메가 9월 급여'!$H:$H,C21, '대치메가 9월 급여'!$A:$A, A21) + sumifs('대치메가 9월 급여'!$Q:$Q,'대치메가 9월 급여'!$M:$M,C21, '대치메가 9월 급여'!$A:$A, A21) + sumifs('대치메가 9월 급여'!$V:$V,'대치메가 9월 급여'!$R:$R,C21, '대치메가 9월 급여'!$A:$A, A21) + sumifs('대치메가 9월 급여'!$AA:$AA,'대치메가 9월 급여'!$W:$W,C21, '대치메가 9월 급여'!$A:$A, A21) + sumifs('대치메가 9월 급여'!$AF:$AF,'대치메가 9월 급여'!$AB:$AB,C21, '대치메가 9월 급여'!$A:$A, A21) + sumifs('대치메가 9월 급여'!$AK:$AK,'대치메가 9월 급여'!$AG:$AG,C21, '대치메가 9월 급여'!$A:$A, A21) -> 16 | E21: X | F21: 11030 | G21: =D21*F21 -> 176480 | H21: =if(E21="O", D21/40*8*F21, 0) -> 0 | I21: =sum(G21:H21) -> 176480
A22: 2주차 | B22: 6 | C22: 안지혜 | D22: =sumifs('대치메가 9월 급여'!$G:$G, '대치메가 9월 급여'!$C:$C, C22, '대치메가 9월 급여'!$A:$A, A22) + sumifs('대치메가 9월 급여'!$L:$L,'대치메가 9월 급여'!$H:$H,C22, '대치메가 9월 급여'!$A:$A, A22) + sumifs('대치메가 9월 급여'!$Q:$Q,'대치메가 9월 급여'!$M:$M,C22, '대치메가 9월 급여'!$A:$A, A22) + sumifs('대치메가 9월 급여'!$V:$V,'대치메가 9월 급여'!$R:$R,C22, '대치메가 9월 급여'!$A:$A, A22) + sumifs('대치메가 9월 급여'!$AA:$AA,'대치메가 9월 급여'!$W:$W,C22, '대치메가 9월 급여'!$A:$A, A22) + sumifs('대치메가 9월 급여'!$AF:$AF,'대치메가 9월 급여'!$AB:$AB,C22, '대치메가 9월 급여'!$A:$A, A22) + sumifs('대치메가 9월 급여'!$AK:$AK,'대치메가 9월 급여'!$AG:$AG,C22, '대치메가 9월 급여'!$A:$A, A22) -> 8.5 | E22: =if(D22 >= 15, "O", "X") -> X | F22: 11030 | G22: =D22*F22 -> 93755 | H22: =if(E22="O", D22/40*8*F22, 0) -> 0 | I22: =sum(G22:H22) -> 93755
A23: 2주차 | B23: 7 | C23: 알리사 | D23: =sumifs('대치메가 9월 급여'!$G:$G, '대치메가 9월 급여'!$C:$C, C23, '대치메가 9월 급여'!$A:$A, A23) + sumifs('대치메가 9월 급여'!$L:$L,'대치메가 9월 급여'!$H:$H,C23, '대치메가 9월 급여'!$A:$A, A23) + sumifs('대치메가 9월 급여'!$Q:$Q,'대치메가 9월 급여'!$M:$M,C23, '대치메가 9월 급여'!$A:$A, A23) + sumifs('대치메가 9월 급여'!$V:$V,'대치메가 9월 급여'!$R:$R,C23, '대치메가 9월 급여'!$A:$A, A23) + sumifs('대치메가 9월 급여'!$AA:$AA,'대치메가 9월 급여'!$W:$W,C23, '대치메가 9월 급여'!$A:$A, A23) + sumifs('대치메가 9월 급여'!$AF:$AF,'대치메가 9월 급여'!$AB:$AB,C23, '대치메가 9월 급여'!$A:$A, A23) + sumifs('대치메가 9월 급여'!$AK:$AK,'대치메가 9월 급여'!$AG:$AG,C23, '대치메가 9월 급여'!$A:$A, A23) -> 19 | E23: =if(D23 >= 15, "O", "X") -> O | F23: 10030 | G23: =D23*F23 -> 190570 | H23: =if(E23="O", D23/40*8*F23, 0) -> 38114 | I23: =sum(G23:H23) -> 228684
A24: 2주차 | B24: 8 | C24: 이주형 | D24: =sumifs('대치메가 9월 급여'!$G:$G, '대치메가 9월 급여'!$C:$C, C24, '대치메가 9월 급여'!$A:$A, A24) + sumifs('대치메가 9월 급여'!$L:$L,'대치메가 9월 급여'!$H:$H,C24, '대치메가 9월 급여'!$A:$A, A24) + sumifs('대치메가 9월 급여'!$Q:$Q,'대치메가 9월 급여'!$M:$M,C24, '대치메가 9월 급여'!$A:$A, A24) + sumifs('대치메가 9월 급여'!$V:$V,'대치메가 9월 급여'!$R:$R,C24, '대치메가 9월 급여'!$A:$A, A24) + sumifs('대치메가 9월 급여'!$AA:$AA,'대치메가 9월 급여'!$W:$W,C24, '대치메가 9월 급여'!$A:$A, A24) + sumifs('대치메가 9월 급여'!$AF:$AF,'대치메가 9월 급여'!$AB:$AB,C24, '대치메가 9월 급여'!$A:$A, A24) + sumifs('대치메가 9월 급여'!$AK:$AK,'대치메가 9월 급여'!$AG:$AG,C24, '대치메가 9월 급여'!$A:$A, A24) -> 17.75 | E24: =if(D24 >= 15, "O", "X") -> O | F24: 11030 | G24: =D24*F24 -> 195782.5 | H24: =if(E24="O", 17/40*8*F24, 0) -> 37502 | I24: =sum(G24:H24) -> 233284.5
A25: 2주차 | B25: 9 | C25: 최제일 | D25: =sumifs('대치메가 9월 급여'!$G:$G, '대치메가 9월 급여'!$C:$C, C25, '대치메가 9월 급여'!$A:$A, A25) + sumifs('대치메가 9월 급여'!$L:$L,'대치메가 9월 급여'!$H:$H,C25, '대치메가 9월 급여'!$A:$A, A25) + sumifs('대치메가 9월 급여'!$Q:$Q,'대치메가 9월 급여'!$M:$M,C25, '대치메가 9월 급여'!$A:$A, A25) + sumifs('대치메가 9월 급여'!$V:$V,'대치메가 9월 급여'!$R:$R,C25, '대치메가 9월 급여'!$A:$A, A25) + sumifs('대치메가 9월 급여'!$AA:$AA,'대치메가 9월 급여'!$W:$W,C25, '대치메가 9월 급여'!$A:$A, A25) + sumifs('대치메가 9월 급여'!$AF:$AF,'대치메가 9월 급여'!$AB:$AB,C25, '대치메가 9월 급여'!$A:$A, A25) + sumifs('대치메가 9월 급여'!$AK:$AK,'대치메가 9월 급여'!$AG:$AG,C25, '대치메가 9월 급여'!$A:$A, A25) -> 0 | E25: =if(D25 >= 15, "O", "X") -> X | F25: 10030 | G25: =D25*F25 -> 0 | H25: =if(E25="O", D25/40*8*F25, 0) -> 0 | I25: =sum(G25:H25) -> 0
A26: 2주차 | B26: 10 | D26: =sumifs('대치메가 9월 급여'!$G:$G, '대치메가 9월 급여'!$C:$C, C26, '대치메가 9월 급여'!$A:$A, A26) + sumifs('대치메가 9월 급여'!$L:$L,'대치메가 9월 급여'!$H:$H,C26, '대치메가 9월 급여'!$A:$A, A26) + sumifs('대치메가 9월 급여'!$Q:$Q,'대치메가 9월 급여'!$M:$M,C26, '대치메가 9월 급여'!$A:$A, A26) + sumifs('대치메가 9월 급여'!$V:$V,'대치메가 9월 급여'!$R:$R,C26, '대치메가 9월 급여'!$A:$A, A26) + sumifs('대치메가 9월 급여'!$AA:$AA,'대치메가 9월 급여'!$W:$W,C26, '대치메가 9월 급여'!$A:$A, A26) + sumifs('대치메가 9월 급여'!$AF:$AF,'대치메가 9월 급여'!$AB:$AB,C26, '대치메가 9월 급여'!$A:$A, A26) + sumifs('대치메가 9월 급여'!$AK:$AK,'대치메가 9월 급여'!$AG:$AG,C26, '대치메가 9월 급여'!$A:$A, A26) -> 0 | E26: =if(D26 >= 15, "O", "X") -> X | F26: 10030 | G26: =D26*F26 -> 0 | H26: =if(E26="O", D26/40*8*F26, 0) -> 0 | I26: =sum(G26:H26) -> 0
A27: 2주차 | B27: 11 | D27: =sumifs('대치메가 9월 급여'!$G:$G, '대치메가 9월 급여'!$C:$C, C27, '대치메가 9월 급여'!$A:$A, A27) + sumifs('대치메가 9월 급여'!$L:$L,'대치메가 9월 급여'!$H:$H,C27, '대치메가 9월 급여'!$A:$A, A27) + sumifs('대치메가 9월 급여'!$Q:$Q,'대치메가 9월 급여'!$M:$M,C27, '대치메가 9월 급여'!$A:$A, A27) + sumifs('대치메가 9월 급여'!$V:$V,'대치메가 9월 급여'!$R:$R,C27, '대치메가 9월 급여'!$A:$A, A27) + sumifs('대치메가 9월 급여'!$AA:$AA,'대치메가 9월 급여'!$W:$W,C27, '대치메가 9월 급여'!$A:$A, A27) + sumifs('대치메가 9월 급여'!$AF:$AF,'대치메가 9월 급여'!$AB:$AB,C27, '대치메가 9월 급여'!$A:$A, A27) + sumifs('대치메가 9월 급여'!$AK:$AK,'대치메가 9월 급여'!$AG:$AG,C27, '대치메가 9월 급여'!$A:$A, A27) -> 0 | E27: =if(D27 >= 15, "O", "X") -> X | F27: 10030 | G27: =D27*F27 -> 0 | H27: =if(E27="O", D27/40*8*F27, 0) -> 0 | I27: =sum(G27:H27) -> 0
A28: 2주차 | B28: 12 | D28: =sumifs('대치메가 9월 급여'!$G:$G, '대치메가 9월 급여'!$C:$C, C28, '대치메가 9월 급여'!$A:$A, A28) + sumifs('대치메가 9월 급여'!$L:$L,'대치메가 9월 급여'!$H:$H,C28, '대치메가 9월 급여'!$A:$A, A28) + sumifs('대치메가 9월 급여'!$Q:$Q,'대치메가 9월 급여'!$M:$M,C28, '대치메가 9월 급여'!$A:$A, A28) + sumifs('대치메가 9월 급여'!$V:$V,'대치메가 9월 급여'!$R:$R,C28, '대치메가 9월 급여'!$A:$A, A28) + sumifs('대치메가 9월 급여'!$AA:$AA,'대치메가 9월 급여'!$W:$W,C28, '대치메가 9월 급여'!$A:$A, A28) + sumifs('대치메가 9월 급여'!$AF:$AF,'대치메가 9월 급여'!$AB:$AB,C28, '대치메가 9월 급여'!$A:$A, A28) + sumifs('대치메가 9월 급여'!$AK:$AK,'대치메가 9월 급여'!$AG:$AG,C28, '대치메가 9월 급여'!$A:$A, A28) -> 0 | E28: =if(D28 >= 15, "O", "X") -> X | F28: 10030 | G28: =D28*F28 -> 0 | H28: =if(E28="O", D28/40*8*F28, 0) -> 0 | I28: =sum(G28:H28) -> 0
A29: 2주차 | B29: 13 | D29: =sumifs('대치메가 9월 급여'!$G:$G, '대치메가 9월 급여'!$C:$C, C29, '대치메가 9월 급여'!$A:$A, A29) + sumifs('대치메가 9월 급여'!$L:$L,'대치메가 9월 급여'!$H:$H,C29, '대치메가 9월 급여'!$A:$A, A29) + sumifs('대치메가 9월 급여'!$Q:$Q,'대치메가 9월 급여'!$M:$M,C29, '대치메가 9월 급여'!$A:$A, A29) + sumifs('대치메가 9월 급여'!$V:$V,'대치메가 9월 급여'!$R:$R,C29, '대치메가 9월 급여'!$A:$A, A29) + sumifs('대치메가 9월 급여'!$AA:$AA,'대치메가 9월 급여'!$W:$W,C29, '대치메가 9월 급여'!$A:$A, A29) + sumifs('대치메가 9월 급여'!$AF:$AF,'대치메가 9월 급여'!$AB:$AB,C29, '대치메가 9월 급여'!$A:$A, A29) + sumifs('대치메가 9월 급여'!$AK:$AK,'대치메가 9월 급여'!$AG:$AG,C29, '대치메가 9월 급여'!$A:$A, A29) -> 0 | E29: =if(D29 >= 15, "O", "X") -> X | F29: 10030 | G29: =D29*F29 -> 0 | H29: =if(E29="O", D29/40*8*F29, 0) -> 0 | I29: =sum(G29:H29) -> 0
A30: 2주차 | B30: 14 | D30: =sumifs('대치메가 9월 급여'!$G:$G, '대치메가 9월 급여'!$C:$C, C30, '대치메가 9월 급여'!$A:$A, A30) + sumifs('대치메가 9월 급여'!$L:$L,'대치메가 9월 급여'!$H:$H,C30, '대치메가 9월 급여'!$A:$A, A30) + sumifs('대치메가 9월 급여'!$Q:$Q,'대치메가 9월 급여'!$M:$M,C30, '대치메가 9월 급여'!$A:$A, A30) + sumifs('대치메가 9월 급여'!$V:$V,'대치메가 9월 급여'!$R:$R,C30, '대치메가 9월 급여'!$A:$A, A30) + sumifs('대치메가 9월 급여'!$AA:$AA,'대치메가 9월 급여'!$W:$W,C30, '대치메가 9월 급여'!$A:$A, A30) + sumifs('대치메가 9월 급여'!$AF:$AF,'대치메가 9월 급여'!$AB:$AB,C30, '대치메가 9월 급여'!$A:$A, A30) + sumifs('대치메가 9월 급여'!$AK:$AK,'대치메가 9월 급여'!$AG:$AG,C30, '대치메가 9월 급여'!$A:$A, A30) -> 0 | E30: =if(D30 >= 15, "O", "X") -> X | F30: 10030 | G30: =D30*F30 -> 0 | H30: =if(E30="O", D30/40*8*F30, 0) -> 0 | I30: =sum(G30:H30) -> 0
A31: 2주차 | B31: 15 | D31: =sumifs('대치메가 9월 급여'!$G:$G, '대치메가 9월 급여'!$C:$C, C31, '대치메가 9월 급여'!$A:$A, A31) + sumifs('대치메가 9월 급여'!$L:$L,'대치메가 9월 급여'!$H:$H,C31, '대치메가 9월 급여'!$A:$A, A31) + sumifs('대치메가 9월 급여'!$Q:$Q,'대치메가 9월 급여'!$M:$M,C31, '대치메가 9월 급여'!$A:$A, A31) + sumifs('대치메가 9월 급여'!$V:$V,'대치메가 9월 급여'!$R:$R,C31, '대치메가 9월 급여'!$A:$A, A31) + sumifs('대치메가 9월 급여'!$AA:$AA,'대치메가 9월 급여'!$W:$W,C31, '대치메가 9월 급여'!$A:$A, A31) + sumifs('대치메가 9월 급여'!$AF:$AF,'대치메가 9월 급여'!$AB:$AB,C31, '대치메가 9월 급여'!$A:$A, A31) + sumifs('대치메가 9월 급여'!$AK:$AK,'대치메가 9월 급여'!$AG:$AG,C31, '대치메가 9월 급여'!$A:$A, A31) -> 0 | E31: =if(D31 >= 15, "O", "X") -> X | F31: 10030 | G31: =D31*F31 -> 0 | H31: =if(E31="O", D31/40*8*F31, 0) -> 0 | I31: =sum(G31:H31) -> 0
A32: 3주차 | B32: 1 | C32: 강순옥 | D32: =sumifs('대치메가 9월 급여'!$G:$G, '대치메가 9월 급여'!$C:$C, C32, '대치메가 9월 급여'!$A:$A, A32) + sumifs('대치메가 9월 급여'!$L:$L,'대치메가 9월 급여'!$H:$H,C32, '대치메가 9월 급여'!$A:$A, A32) + sumifs('대치메가 9월 급여'!$Q:$Q,'대치메가 9월 급여'!$M:$M,C32, '대치메가 9월 급여'!$A:$A, A32) + sumifs('대치메가 9월 급여'!$V:$V,'대치메가 9월 급여'!$R:$R,C32, '대치메가 9월 급여'!$A:$A, A32) + sumifs('대치메가 9월 급여'!$AA:$AA,'대치메가 9월 급여'!$W:$W,C32, '대치메가 9월 급여'!$A:$A, A32) + sumifs('대치메가 9월 급여'!$AF:$AF,'대치메가 9월 급여'!$AB:$AB,C32, '대치메가 9월 급여'!$A:$A, A32) + sumifs('대치메가 9월 급여'!$AK:$AK,'대치메가 9월 급여'!$AG:$AG,C32, '대치메가 9월 급여'!$A:$A, A32) -> 42.5 | E32: =if(D32 >= 15, "O", "X") -> O | F32: 10030 | G32: =D32*F32 -> 426275 | H32: =if(E32="O", D32/40*8*F32, 0) -> 85255 | I32: =sum(G32:H32) -> 511530
A33: 3주차 | B33: 2 | C33: 배은솔 | D33: =sumifs('대치메가 9월 급여'!$G:$G, '대치메가 9월 급여'!$C:$C, C33, '대치메가 9월 급여'!$A:$A, A33) + sumifs('대치메가 9월 급여'!$L:$L,'대치메가 9월 급여'!$H:$H,C33, '대치메가 9월 급여'!$A:$A, A33) + sumifs('대치메가 9월 급여'!$Q:$Q,'대치메가 9월 급여'!$M:$M,C33, '대치메가 9월 급여'!$A:$A, A33) + sumifs('대치메가 9월 급여'!$V:$V,'대치메가 9월 급여'!$R:$R,C33, '대치메가 9월 급여'!$A:$A, A33) + sumifs('대치메가 9월 급여'!$AA:$AA,'대치메가 9월 급여'!$W:$W,C33, '대치메가 9월 급여'!$A:$A, A33) + sumifs('대치메가 9월 급여'!$AF:$AF,'대치메가 9월 급여'!$AB:$AB,C33, '대치메가 9월 급여'!$A:$A, A33) + sumifs('대치메가 9월 급여'!$AK:$AK,'대치메가 9월 급여'!$AG:$AG,C33, '대치메가 9월 급여'!$A:$A, A33) -> 7 | E33: =if(D33 >= 15, "O", "X") -> X | F33: 10030 | G33: =D33*F33 -> 70210 | H33: =if(E33="O", D33/40*8*F33, 0) -> 0 | I33: =sum(G33:H33) -> 70210
A34: 3주차 | B34: 3 | C34: 김석원 | D34: =sumifs('대치메가 9월 급여'!$G:$G, '대치메가 9월 급여'!$C:$C, C34, '대치메가 9월 급여'!$A:$A, A34) + sumifs('대치메가 9월 급여'!$L:$L,'대치메가 9월 급여'!$H:$H,C34, '대치메가 9월 급여'!$A:$A, A34) + sumifs('대치메가 9월 급여'!$Q:$Q,'대치메가 9월 급여'!$M:$M,C34, '대치메가 9월 급여'!$A:$A, A34) + sumifs('대치메가 9월 급여'!$V:$V,'대치메가 9월 급여'!$R:$R,C34, '대치메가 9월 급여'!$A:$A, A34) + sumifs('대치메가 9월 급여'!$AA:$AA,'대치메가 9월 급여'!$W:$W,C34, '대치메가 9월 급여'!$A:$A, A34) + sumifs('대치메가 9월 급여'!$AF:$AF,'대치메가 9월 급여'!$AB:$AB,C34, '대치메가 9월 급여'!$A:$A, A34) + sumifs('대치메가 9월 급여'!$AK:$AK,'대치메가 9월 급여'!$AG:$AG,C34, '대치메가 9월 급여'!$A:$A, A34) -> 42 | E34: =if(D34 >= 15, "O", "X") -> O | F34: 11030 | G34: =D34*F34 -> 463260 | H34: =if(E34="O", 40/40*8*F34, 0) -> 88240 | I34: =sum(G34:H34) -> 551500
A35: 3주차 | B35: 4 | C35: 김현지 | D35: =sumifs('대치메가 9월 급여'!$G:$G, '대치메가 9월 급여'!$C:$C, C35, '대치메가 9월 급여'!$A:$A, A35) + sumifs('대치메가 9월 급여'!$L:$L,'대치메가 9월 급여'!$H:$H,C35, '대치메가 9월 급여'!$A:$A, A35) + sumifs('대치메가 9월 급여'!$Q:$Q,'대치메가 9월 급여'!$M:$M,C35, '대치메가 9월 급여'!$A:$A, A35) + sumifs('대치메가 9월 급여'!$V:$V,'대치메가 9월 급여'!$R:$R,C35, '대치메가 9월 급여'!$A:$A, A35) + sumifs('대치메가 9월 급여'!$AA:$AA,'대치메가 9월 급여'!$W:$W,C35, '대치메가 9월 급여'!$A:$A, A35) + sumifs('대치메가 9월 급여'!$AF:$AF,'대치메가 9월 급여'!$AB:$AB,C35, '대치메가 9월 급여'!$A:$A, A35) + sumifs('대치메가 9월 급여'!$AK:$AK,'대치메가 9월 급여'!$AG:$AG,C35, '대치메가 9월 급여'!$A:$A, A35) -> 21 | E35: =if(D35 >= 15, "O", "X") -> O | F35: 10030 | G35: =D35*F35 -> 210630 | H35: =if(E35="O", 21/40*8*F35, 0) -> 42126 | I35: =sum(G35:H35) -> 252756
A36: 3주차 | B36: 5 | C36: 문병준 | D36: =sumifs('대치메가 9월 급여'!$G:$G, '대치메가 9월 급여'!$C:$C, C36, '대치메가 9월 급여'!$A:$A, A36) + sumifs('대치메가 9월 급여'!$L:$L,'대치메가 9월 급여'!$H:$H,C36, '대치메가 9월 급여'!$A:$A, A36) + sumifs('대치메가 9월 급여'!$Q:$Q,'대치메가 9월 급여'!$M:$M,C36, '대치메가 9월 급여'!$A:$A, A36) + sumifs('대치메가 9월 급여'!$V:$V,'대치메가 9월 급여'!$R:$R,C36, '대치메가 9월 급여'!$A:$A, A36) + sumifs('대치메가 9월 급여'!$AA:$AA,'대치메가 9월 급여'!$W:$W,C36, '대치메가 9월 급여'!$A:$A, A36) + sumifs('대치메가 9월 급여'!$AF:$AF,'대치메가 9월 급여'!$AB:$AB,C36, '대치메가 9월 급여'!$A:$A, A36) + sumifs('대치메가 9월 급여'!$AK:$AK,'대치메가 9월 급여'!$AG:$AG,C36, '대치메가 9월 급여'!$A:$A, A36) -> 16.5 | E36: X | F36: 11030 | G36: =D36*F36 -> 181995 | H36: =if(E36="O", D36/40*8*F36, 0) -> 0 | I36: =sum(G36:H36) -> 181995
A37: 3주차 | B37: 6 | C37: 안지혜 | D37: =sumifs('대치메가 9월 급여'!$G:$G, '대치메가 9월 급여'!$C:$C, C37, '대치메가 9월 급여'!$A:$A, A37) + sumifs('대치메가 9월 급여'!$L:$L,'대치메가 9월 급여'!$H:$H,C37, '대치메가 9월 급여'!$A:$A, A37) + sumifs('대치메가 9월 급여'!$Q:$Q,'대치메가 9월 급여'!$M:$M,C37, '대치메가 9월 급여'!$A:$A, A37) + sumifs('대치메가 9월 급여'!$V:$V,'대치메가 9월 급여'!$R:$R,C37, '대치메가 9월 급여'!$A:$A, A37) + sumifs('대치메가 9월 급여'!$AA:$AA,'대치메가 9월 급여'!$W:$W,C37, '대치메가 9월 급여'!$A:$A, A37) + sumifs('대치메가 9월 급여'!$AF:$AF,'대치메가 9월 급여'!$AB:$AB,C37, '대치메가 9월 급여'!$A:$A, A37) + sumifs('대치메가 9월 급여'!$AK:$AK,'대치메가 9월 급여'!$AG:$AG,C37, '대치메가 9월 급여'!$A:$A, A37) -> 8.5 | E37: =if(D37 >= 15, "O", "X") -> X | F37: 11030 | G37: =D37*F37 -> 93755 | H37: =if(E37="O", D37/40*8*F37, 0) -> 0 | I37: =sum(G37:H37) -> 93755
A38: 3주차 | B38: 7 | C38: 알리사 | D38: =sumifs('대치메가 9월 급여'!$G:$G, '대치메가 9월 급여'!$C:$C, C38, '대치메가 9월 급여'!$A:$A, A38) + sumifs('대치메가 9월 급여'!$L:$L,'대치메가 9월 급여'!$H:$H,C38, '대치메가 9월 급여'!$A:$A, A38) + sumifs('대치메가 9월 급여'!$Q:$Q,'대치메가 9월 급여'!$M:$M,C38, '대치메가 9월 급여'!$A:$A, A38) + sumifs('대치메가 9월 급여'!$V:$V,'대치메가 9월 급여'!$R:$R,C38, '대치메가 9월 급여'!$A:$A, A38) + sumifs('대치메가 9월 급여'!$AA:$AA,'대치메가 9월 급여'!$W:$W,C38, '대치메가 9월 급여'!$A:$A, A38) + sumifs('대치메가 9월 급여'!$AF:$AF,'대치메가 9월 급여'!$AB:$AB,C38, '대치메가 9월 급여'!$A:$A, A38) + sumifs('대치메가 9월 급여'!$AK:$AK,'대치메가 9월 급여'!$AG:$AG,C38, '대치메가 9월 급여'!$A:$A, A38) -> 19 | E38: =if(D38 >= 15, "O", "X") -> O | F38: 10030 | G38: =D38*F38 -> 190570 | H38: =if(E38="O", D38/40*8*F38, 0) -> 38114 | I38: =sum(G38:H38) -> 228684
A39: 3주차 | B39: 8 | C39: 이주형 | D39: =sumifs('대치메가 9월 급여'!$G:$G, '대치메가 9월 급여'!$C:$C, C39, '대치메가 9월 급여'!$A:$A, A39) + sumifs('대치메가 9월 급여'!$L:$L,'대치메가 9월 급여'!$H:$H,C39, '대치메가 9월 급여'!$A:$A, A39) + sumifs('대치메가 9월 급여'!$Q:$Q,'대치메가 9월 급여'!$M:$M,C39, '대치메가 9월 급여'!$A:$A, A39) + sumifs('대치메가 9월 급여'!$V:$V,'대치메가 9월 급여'!$R:$R,C39, '대치메가 9월 급여'!$A:$A, A39) + sumifs('대치메가 9월 급여'!$AA:$AA,'대치메가 9월 급여'!$W:$W,C39, '대치메가 9월 급여'!$A:$A, A39) + sumifs('대치메가 9월 급여'!$AF:$AF,'대치메가 9월 급여'!$AB:$AB,C39, '대치메가 9월 급여'!$A:$A, A39) + sumifs('대치메가 9월 급여'!$AK:$AK,'대치메가 9월 급여'!$AG:$AG,C39, '대치메가 9월 급여'!$A:$A, A39) -> 17.75 | E39: =if(D39 >= 15, "O", "X") -> O | F39: 11030 | G39: =D39*F39 -> 195782.5 | H39: =if(E39="O", 17/40*8*F39, 0) -> 37502 | I39: =sum(G39:H39) -> 233284.5
A40: 3주차 | B40: 9 | C40: 최제일 | D40: =sumifs('대치메가 9월 급여'!$G:$G, '대치메가 9월 급여'!$C:$C, C40, '대치메가 9월 급여'!$A:$A, A40) + sumifs('대치메가 9월 급여'!$L:$L,'대치메가 9월 급여'!$H:$H,C40, '대치메가 9월 급여'!$A:$A, A40) + sumifs('대치메가 9월 급여'!$Q:$Q,'대치메가 9월 급여'!$M:$M,C40, '대치메가 9월 급여'!$A:$A, A40) + sumifs('대치메가 9월 급여'!$V:$V,'대치메가 9월 급여'!$R:$R,C40, '대치메가 9월 급여'!$A:$A, A40) + sumifs('대치메가 9월 급여'!$AA:$AA,'대치메가 9월 급여'!$W:$W,C40, '대치메가 9월 급여'!$A:$A, A40) + sumifs('대치메가 9월 급여'!$AF:$AF,'대치메가 9월 급여'!$AB:$AB,C40, '대치메가 9월 급여'!$A:$A, A40) + sumifs('대치메가 9월 급여'!$AK:$AK,'대치메가 9월 급여'!$AG:$AG,C40, '대치메가 9월 급여'!$A:$A, A40) -> 0 | E40: =if(D40 >= 15, "O", "X") -> X | F40: 11030 | G40: =D40*F40 -> 0 | H40: =if(E40="O", D40/40*8*F40, 0) -> 0 | I40: =sum(G40:H40) -> 0
...

Sheet 삼성메가 9월 신고
A1: 구분 | B1: 이름 | C1: 주민번호 | D1: 입사일 | E1: 근무요일 | F1: 근무시간 | G1: 현재 주 소정근로시간 법정 휴게제외 | H1: 일 휴게시간 | I1: 조정 후 주 소정근로시간 | J1: 실급여 | K1: 신고 급여 | L1: 특이사항 | M1: 만근수당 대상 | N1: 지급여부 | O1: 비고 | P1: 은행 | Q1: 계좌번호
A2: 1 | B2: 강순옥 | D2: 2023.05.25 | E2: 평일 | F2: 점주 | J2: =sumif('대치 9월 주급여'!$M$2:$Q$16, B2, '대치 9월 주급여'!$S$2:$S$16)+sumif('삼성 9월 주급여'!$M$2:$Q$16, B2, '삼성 9월 주급여'!$S$2:$S$16) -> 2262768 | K2: =J2 -> 2262768 | L2: 점주
A3: 2 | B3: 고상원 | C3: 040323-3076619 | D3: 2024.11.20 | E3: 토, 일 | F3: 18:30~23:00 | G3: 9 | J3: =sumif('대치 9월 주급여'!$M$2:$Q$16, B3, '대치 9월 주급여'!$S$2:$S$16)+sumif('삼성 9월 주급여'!$M$2:$Q$20, B3, '삼성 9월 주급여'!$S$2:$S$16) -> 424655 | K3: =sumif('대치 9월 주급여'!$M$2:$Q$16, B3, '대치 9월 주급여'!$Q$2:$Q$16)+sumif('삼성 9월 주급여'!$M$2:$Q$20, B3, '삼성 9월 주급여'!$Q$2:$Q$20) -> 424655 | L3: 주15시간 미만
A4: 3 | B4: 김승만 | C4: 840523-1558211 | D4: 2025.04.22 | E4: 월~금 | F4: 23:00~07:00 | G4: 40 | J4: =sumif('대치 9월 주급여'!$M$2:$Q$16, B4, '대치 9월 주급여'!$S$2:$S$16)+sumif('삼성 9월 주급여'!$M$2:$Q$20, B4, '삼성 9월 주급여'!$S$2:$S$16) -> 2618515 | K4: =sumif('대치 9월 주급여'!$M$2:$Q$16, B4, '대치 9월 주급여'!$Q$2:$Q$16)+sumif('삼성 9월 주급여'!$M$2:$Q$20, B4, '삼성 9월 주급여'!$Q$2:$Q$20) -> 2707865 | L4: 3.3% 사업소득신고
A5: 4 | B5: 박진형 | C5: 880607-1122820 | D5: 2023.05.28 | E5: 일요일 | F5: 07:00~15:00 | G5: 8 | J5: =sumif('대치 9월 주급여'!$M$2:$Q$16, B5, '대치 9월 주급여'!$S$2:$S$16)+sumif('삼성 9월 주급여'!$M$2:$Q$20, B5, '삼성 9월 주급여'!$S$2:$S$16) -> 190570 | K5: =sumif('대치 9월 주급여'!$M$2:$Q$16, B5, '대치 9월 주급여'!$Q$2:$Q$16)+sumif('삼성 9월 주급여'!$M$2:$Q$20, B5, '삼성 9월 주급여'!$Q$2:$Q$20) -> 190570 | L5: 주15시간 미만
A6: 6 | B6: 양현서 | C6: 000502-4520022 | D6: 2025.07.31 | E6: 금, 토 | F6: 23:00~07:00 | G6: 16 | J6: =sumif('대치 9월 주급여'!$M$2:$Q$16, B6, '대치 9월 주급여'!$S$2:$S$16)+sumif('삼성 9월 주급여'!$M$2:$Q$20, B6, '삼성 9월 주급여'!$S$2:$S$16) -> 870348 | K6: =sumif('대치 9월 주급여'!$M$2:$Q$16, B6, '대치 9월 주급여'!$Q$2:$Q$16)+sumif('삼성 9월 주급여'!$M$2:$Q$20, B6, '삼성 9월 주급여'!$Q$2:$Q$20) -> 900048 | L6: 3.3% 사업소득신고
A7: 7 | B7: 오승윤 | C7: 040630-3216015 | D7: 2025.08.16 | E7: 월~금 | F7: 15:00~18:30 | G7: 16.5 | J7: =sumif('대치 9월 주급여'!$M$2:$Q$16, B7, '대치 9월 주급여'!$S$2:$S$16)+sumif('삼성 9월 주급여'!$M$2:$Q$20, B7, '삼성 9월 주급여'!$S$2:$S$16) -> 1484716 | K7: =sumif('대치 9월 주급여'!$M$2:$Q$16, B7, '대치 9월 주급여'!$Q$2:$Q$16)+sumif('삼성 9월 주급여'!$M$2:$Q$20, B7, '삼성 9월 주급여'!$Q$2:$Q$20) -> 1535376 | L7: 3.3% 사업소득신고
